<sdf version='1.6'>
  <world name='default'>
    <light name='sun' type='directional'>
      <cast_shadows>1</cast_shadows>
      <pose frame=''>0 0 10 0 -0 0</pose>
      <diffuse>0.8 0.8 0.8 1</diffuse>
      <specular>0.2 0.2 0.2 1</specular>
      <attenuation>
        <range>1000</range>
        <constant>0.9</constant>
        <linear>0.01</linear>
        <quadratic>0.001</quadratic>
      </attenuation>
      <direction>-0.5 0.1 -0.9</direction>
    </light>
    <model name='ground_plane'>
      <static>1</static>
      <link name='link'>
        <collision name='collision'>
          <geometry>
            <plane>
              <normal>0 0 1</normal>
              <size>100 100</size>
            </plane>
          </geometry>
          <surface>
            <contact>
              <collide_bitmask>65535</collide_bitmask>
              <ode/>
            </contact>
            <friction>
              <ode>
                <mu>100</mu>
                <mu2>50</mu2>
              </ode>
              <torsional>
                <ode/>
              </torsional>
            </friction>
            <bounce/>
          </surface>
          <max_contacts>10</max_contacts>
        </collision>
        <visual name='visual'>
          <cast_shadows>0</cast_shadows>
          <geometry>
            <plane>
              <normal>0 0 1</normal>
              <size>100 100</size>
            </plane>
          </geometry>
          <material>
            <script>
              <uri>file://media/materials/scripts/gazebo.material</uri>
              <name>Gazebo/Grey</name>
            </script>
          </material>
        </visual>
        <self_collide>0</self_collide>
        <enable_wind>0</enable_wind>
        <kinematic>0</kinematic>
      </link>
    </model>
    <gravity>0 0 -9.8</gravity>
    <magnetic_field>6e-06 2.3e-05 -4.2e-05</magnetic_field>
    <atmosphere type='adiabatic'/>
    <physics name='default_physics' default='0' type='ode'>
      <max_step_size>0.001</max_step_size>
      <real_time_factor>1</real_time_factor>
      <real_time_update_rate>1000</real_time_update_rate>
    </physics>
    <scene>
      <ambient>0.4 0.4 0.4 1</ambient>
      <background>0.7 0.7 0.7 1</background>
      <shadows>1</shadows>
    </scene>
    <audio>
      <device>default</device>
    </audio>
    <wind/>
    <spherical_coordinates>
      <surface_model>EARTH_WGS84</surface_model>
      <latitude_deg>0</latitude_deg>
      <longitude_deg>0</longitude_deg>
      <elevation>0</elevation>
      <heading_deg>0</heading_deg>
    </spherical_coordinates>
    <model name='csi_rover'>
      <link name='chassis'>
        <pose frame=''>0 0 0 0 -0 0</pose>
        <inertial>
          <pose frame=''>0.03653 0 0.425655 0 -0 0</pose>
          <mass>8.40401</mass>
          <inertia>
            <ixx>0.0821417</ixx>
            <ixy>0</ixy>
            <ixz>-0.0803865</ixz>
            <iyy>0.315768</iyy>
            <iyz>0</iyz>
            <izz>0.294805</izz>
          </inertia>
        </inertial>
        <collision name='chassis_fixed_joint_lump__collision_collision'>
          <pose frame=''>0 0 0.4125 0 -0 0</pose>
          <geometry>
            <box>
              <size>0.75 0.625 0.168275</size>
            </box>
          </geometry>
          <max_contacts>10</max_contacts>
          <surface>
            <contact>
              <ode/>
            </contact>
            <bounce/>
            <friction>
              <torsional>
                <ode/>
              </torsional>
              <ode/>
            </friction>
          </surface>
        </collision>
        <collision name='chassis_fixed_joint_lump__imu_link_collision_1'>
          <pose frame=''>0.4 0 0.6875 0 -0 0</pose>
          <geometry>
            <box>
              <size>0.08 0.08 0.08</size>
            </box>
          </geometry>
          <surface>
            <contact>
              <ode/>
            </contact>
            <friction>
              <ode/>
              <torsional>
                <ode/>
              </torsional>
            </friction>
            <bounce/>
          </surface>
          <max_contacts>10</max_contacts>
        </collision>
        <collision name='chassis_fixed_joint_lump__lidar_link_collision_2'>
          <pose frame=''>0 0 0.7375 0 -0 0</pose>
          <geometry>
            <box>
              <size>0.1 0.1 0.1</size>
            </box>
          </geometry>
          <surface>
            <contact>
              <ode/>
            </contact>
            <friction>
              <ode/>
              <torsional>
                <ode/>
              </torsional>
            </friction>
            <bounce/>
          </surface>
          <max_contacts>10</max_contacts>
        </collision>
        <collision name='chassis_fixed_joint_lump__main_camera_link_collision_3'>
          <pose frame=''>0.85 0 0.6875 0 -0 0</pose>
          <geometry>
            <box>
              <size>0.08 0.08 0.08</size>
            </box>
          </geometry>
          <max_contacts>10</max_contacts>
          <surface>
            <contact>
              <ode/>
            </contact>
            <bounce/>
            <friction>
              <torsional>
                <ode/>
              </torsional>
              <ode/>
            </friction>
          </surface>
        </collision>
        <collision name='chassis_fixed_joint_lump__left_camera_link_collision_4'>
          <pose frame=''>0.91 0.2 0.6875 0 -0 0</pose>
          <geometry>
            <box>
              <size>0.08 0.08 0.08</size>
            </box>
          </geometry>
          <surface>
            <contact>
              <ode/>
            </contact>
            <friction>
              <ode/>
              <torsional>
                <ode/>
              </torsional>
            </friction>
            <bounce/>
          </surface>
          <max_contacts>10</max_contacts>
        </collision>
        <collision name='chassis_fixed_joint_lump__right_camera_link_collision_5'>
          <pose frame=''>0.91 -0.2 0.6875 0 -0 0</pose>
          <geometry>
            <box>
              <size>0.08 0.08 0.08</size>
            </box>
          </geometry>
          <max_contacts>10</max_contacts>
          <surface>
            <contact>
              <ode/>
            </contact>
            <bounce/>
            <friction>
              <torsional>
                <ode/>
              </torsional>
              <ode/>
            </friction>
          </surface>
        </collision>
        <visual name='chassis_fixed_joint_lump__visual_visual'>
          <pose frame=''>0 0 0.4125 0 -0 0</pose>
          <geometry>
            <mesh>
              <scale>0.15 0.15 0.15</scale>
              <uri>/home/csi/Workspace/SRC-Phase2/src/csi_rover_description/meshes/robot_body.dae</uri>
            </mesh>
          </geometry>
        </visual>
        <visual name='chassis_fixed_joint_lump__imu_link_visual_1'>
          <pose frame=''>0.4 0 0.6875 0 -0 0</pose>
          <geometry>
            <box>
              <size>0.08 0.08 0.08</size>
            </box>
          </geometry>
          <material>
            <script>
              <uri>__default__</uri>
              <name>__default__</name>
            </script>
          </material>
        </visual>
        <visual name='chassis_fixed_joint_lump__visual_visual_2'>
          <pose frame=''>0.7874 0.936625 0.55 0 -0 0</pose>
          <geometry>
            <box>
              <size>0.75 0.15625 0.168275</size>
            </box>
          </geometry>
        </visual>
        <visual name='chassis_fixed_joint_lump__visual_visual_3'>
          <pose frame=''>-0.7874 0.936625 0.55 0 -0 0</pose>
          <geometry>
            <box>
              <size>0.75 0.15625 0.168275</size>
            </box>
          </geometry>
        </visual>
        <visual name='chassis_fixed_joint_lump__lidar_link_visual_4'>
          <pose frame=''>0 0 0.7375 0 -0 0</pose>
          <geometry>
            <mesh>
              <scale>2 2 2</scale>
              <uri>/home/csi/Workspace/SRC-Phase2/src/csi_rover_description/meshes/hokuyo.dae</uri>
            </mesh>
          </geometry>
          <material>
            <script>
              <uri>__default__</uri>
              <name>__default__</name>
            </script>
          </material>
        </visual>
        <visual name='chassis_fixed_joint_lump__main_camera_link_visual_5'>
          <pose frame=''>0.85 0 0.6875 0 -0 0</pose>
          <geometry>
            <mesh>
              <scale>0.006 0.006 0.006</scale>
              <uri>/home/csi/Workspace/SRC-Phase2/src/csi_rover_description/meshes/camera.dae</uri>
            </mesh>
          </geometry>
        </visual>
        <visual name='chassis_fixed_joint_lump__left_camera_link_visual_6'>
          <pose frame=''>0.91 0.2 0.6875 0 -0 0</pose>
          <geometry>
            <box>
              <size>0.08 0.08 0.08</size>
            </box>
          </geometry>
          <material>
            <script>
              <uri>__default__</uri>
              <name>__default__</name>
            </script>
          </material>
        </visual>
        <visual name='chassis_fixed_joint_lump__right_camera_link_visual_7'>
          <pose frame=''>0.91 -0.2 0.6875 0 -0 0</pose>
          <geometry>
            <box>
              <size>0.08 0.08 0.08</size>
            </box>
          </geometry>
        </visual>
        <visual name='chassis_fixed_joint_lump__visual_visual_8'>
          <pose frame=''>0.7874 -0.936625 0.55 0 -0 0</pose>
          <geometry>
            <box>
              <size>0.75 0.15625 0.168275</size>
            </box>
          </geometry>
        </visual>
        <visual name='chassis_fixed_joint_lump__visual_visual_9'>
          <pose frame=''>-0.7874 -0.936625 0.55 0 -0 0</pose>
          <geometry>
            <box>
              <size>0.75 0.15625 0.168275</size>
            </box>
          </geometry>
        </visual>
        <velocity_decay/>
        <velocity_decay/>
        <sensor name='imu_sensor' type='imu'>
          <always_on>1</always_on>
          <update_rate>100</update_rate>
          <visualize>1</visualize>
          <plugin name='imu_plugin' filename='libgazebo_ros_imu_sensor.so'>
            <robotNamespace>/csi_rover</robotNamespace>
            <topicName>imu</topicName>
            <bodyName>imu_link</bodyName>
            <updateRateHZ>30.0</updateRateHZ>
            <gaussianNoise>0.0</gaussianNoise>
            <xyzOffset>0 0 0</xyzOffset>
            <rpyOffset>0 0 0</rpyOffset>
            <frameName>imu_link</frameName>
          </plugin>
          <pose frame=''>0.4 0 0 0 -0 0</pose>
          <imu/>
        </sensor>
        <gravity>1</gravity>
        <velocity_decay/>
        <sensor name='head_hokuyo_sensor' type='gpu_ray'>
          <visualize>0</visualize>
          <update_rate>40</update_rate>
          <ray>
            <scan>
              <horizontal>
                <samples>720</samples>
                <resolution>1</resolution>
                <min_angle>-2</min_angle>
                <max_angle>2</max_angle>
              </horizontal>
            </scan>
            <range>
              <min>0.1</min>
              <max>30</max>
              <resolution>0.01</resolution>
            </range>
            <noise>
              <type>gaussian</type>
              <mean>0</mean>
              <stddev>0.01</stddev>
            </noise>
          </ray>
          <plugin name='gazebo_ros_head_hokuyo_controller' filename='libgazebo_ros_gpu_laser.so'>
            <topicName>/csi_rover/laser/scan</topicName>
            <frameName>lidar_link</frameName>
            <robotNamespace>/</robotNamespace>
          </plugin>
          <pose frame=''>0 0 0.7375 0 -0 0</pose>
        </sensor>
        <gravity>1</gravity>
        <velocity_decay/>
        <sensor name='stereo_camera' type='multicamera'>
          <update_rate>30</update_rate>
          <camera name='left'>
            <horizontal_fov>1.22173</horizontal_fov>
            <image>
              <width>1280</width>
              <height>720</height>
              <format>R8G8B8</format>
            </image>
            <clip>
              <near>0.02</near>
              <far>300</far>
            </clip>
            <noise>
              <type>gaussian</type>
              <mean>0</mean>
              <stddev>0.007</stddev>
            </noise>
          </camera>
          <camera name='right'>
            <pose frame=''>0 -0.4 0 0 -0 0</pose>
            <horizontal_fov>1.22173</horizontal_fov>
            <image>
              <width>1280</width>
              <height>720</height>
              <format>R8G8B8</format>
            </image>
            <clip>
              <near>0.02</near>
              <far>300</far>
            </clip>
            <noise>
              <type>gaussian</type>
              <mean>0</mean>
              <stddev>0.007</stddev>
            </noise>
          </camera>
          <plugin name='stereo_camera_controller' filename='libgazebo_ros_multicamera.so'>
            <alwaysOn>1</alwaysOn>
            <updateRate>0.0</updateRate>
            <cameraName>csi_rover/camera</cameraName>
            <imageTopicName>image_raw</imageTopicName>
            <cameraInfoTopicName>camera_info</cameraInfoTopicName>
            <frameName>left_camera_link</frameName>
            <rightFrameName>right_camera_link</rightFrameName>
            <hackBaseline>0.40</hackBaseline>
            <distortionK1>0.0</distortionK1>
            <distortionK2>0.0</distortionK2>
            <distortionK3>0.0</distortionK3>
            <distortionT1>0.0</distortionT1>
            <distortionT2>0.0</distortionT2>
            <robotNamespace>/</robotNamespace>
          </plugin>
          <pose frame=''>0.91 0.2 0.6875 0 -0 0</pose>
        </sensor>
        <self_collide>0</self_collide>
        <enable_wind>0</enable_wind>
        <kinematic>0</kinematic>
      </link>
      <link name='left_front_axle_link'>
        <pose frame=''>0.7874 0.936625 0.106725 0 -0 0</pose>
        <inertial>
          <pose frame=''>0 0 0 0 -0 0</pose>
          <mass>0.001</mass>
          <inertia>
            <ixx>0.001</ixx>
            <ixy>0</ixy>
            <ixz>0</ixz>
            <iyy>0.001</iyy>
            <iyz>0</iyz>
            <izz>0.0001</izz>
          </inertia>
        </inertial>
        <visual name='left_front_axle_link_fixed_joint_lump__visual_visual'>
          <pose frame=''>0 0 0 3.14159 1.57079 -1.57089</pose>
          <geometry>
            <cylinder>
              <length>0.2</length>
              <radius>0.05</radius>
            </cylinder>
          </geometry>
        </visual>
        <self_collide>0</self_collide>
        <enable_wind>0</enable_wind>
        <kinematic>0</kinematic>
      </link>
      <joint name='left_front_steering_joint' type='revolute'>
        <child>left_front_axle_link</child>
        <parent>chassis</parent>
        <axis>
          <xyz>0 0 1</xyz>
          <limit>
            <lower>-1.5707</lower>
            <upper>1.5707</upper>
            <effort>10</effort>
            <velocity>15</velocity>
          </limit>
          <dynamics>
            <spring_reference>0</spring_reference>
            <spring_stiffness>0</spring_stiffness>
          </dynamics>
          <use_parent_model_frame>1</use_parent_model_frame>
        </axis>
      </joint>
      <link name='left_front_wheel'>
        <pose frame=''>0.7874 0.936625 0.106725 0 -0 0</pose>
        <inertial>
          <pose frame=''>0 0 0 1.5707 -0 0</pose>
          <mass>2</mass>
          <inertia>
            <ixx>0.4</ixx>
            <ixy>0</ixy>
            <ixz>0</ixz>
            <iyy>0.4</iyy>
            <iyz>0</iyz>
            <izz>0.2</izz>
          </inertia>
        </inertial>
        <collision name='left_front_wheel_collision'>
          <pose frame=''>0 0 0 1.5707 -0 0</pose>
          <geometry>
            <cylinder>
              <length>0.168275</length>
              <radius>0.275</radius>
            </cylinder>
          </geometry>
          <max_contacts>10</max_contacts>
          <surface>
            <contact>
              <ode/>
            </contact>
            <bounce/>
            <friction>
              <torsional>
                <ode/>
              </torsional>
              <ode/>
            </friction>
          </surface>
        </collision>
        <visual name='left_front_wheel_visual'>
          <pose frame=''>0 0 0 1.5707 -0 0</pose>
          <geometry>
            <mesh>
              <scale>0.12 0.12 0.12</scale>
              <uri>/home/csi/Workspace/SRC-Phase2/src/csi_rover_description/meshes/wheel.dae</uri>
            </mesh>
          </geometry>
        </visual>
        <self_collide>0</self_collide>
        <enable_wind>0</enable_wind>
        <kinematic>0</kinematic>
      </link>
      <joint name='left_front_axle' type='revolute'>
        <child>left_front_wheel</child>
        <parent>left_front_axle_link</parent>
        <axis>
          <xyz>0 1 0</xyz>
          <limit>
            <lower>-1e+16</lower>
            <upper>1e+16</upper>
          </limit>
          <dynamics>
            <spring_reference>0</spring_reference>
            <spring_stiffness>0</spring_stiffness>
          </dynamics>
          <use_parent_model_frame>1</use_parent_model_frame>
        </axis>
      </joint>
      <link name='left_rear_axle_link'>
        <pose frame=''>-0.7874 0.936625 0.106725 0 -0 0</pose>
        <inertial>
          <pose frame=''>0 0 0 0 -0 0</pose>
          <mass>0.001</mass>
          <inertia>
            <ixx>0.001</ixx>
            <ixy>0</ixy>
            <ixz>0</ixz>
            <iyy>0.001</iyy>
            <iyz>0</iyz>
            <izz>0.0001</izz>
          </inertia>
        </inertial>
        <visual name='left_rear_axle_link_fixed_joint_lump__visual_visual'>
          <pose frame=''>0 0 0 3.14159 1.57079 -1.57089</pose>
          <geometry>
            <cylinder>
              <length>0.2</length>
              <radius>0.05</radius>
            </cylinder>
          </geometry>
        </visual>
        <self_collide>0</self_collide>
        <enable_wind>0</enable_wind>
        <kinematic>0</kinematic>
      </link>
      <joint name='left_rear_steering_joint' type='revolute'>
        <child>left_rear_axle_link</child>
        <parent>chassis</parent>
        <axis>
          <xyz>0 0 1</xyz>
          <limit>
            <lower>-1.5707</lower>
            <upper>1.5707</upper>
            <effort>10</effort>
            <velocity>15</velocity>
          </limit>
          <dynamics>
            <spring_reference>0</spring_reference>
            <spring_stiffness>0</spring_stiffness>
          </dynamics>
          <use_parent_model_frame>1</use_parent_model_frame>
        </axis>
      </joint>
      <link name='left_rear_wheel'>
        <pose frame=''>-0.7874 0.936625 0.106725 0 -0 0</pose>
        <inertial>
          <pose frame=''>0 0 0 1.5707 -0 0</pose>
          <mass>2</mass>
          <inertia>
            <ixx>0.4</ixx>
            <ixy>0</ixy>
            <ixz>0</ixz>
            <iyy>0.4</iyy>
            <iyz>0</iyz>
            <izz>0.2</izz>
          </inertia>
        </inertial>
        <collision name='left_rear_wheel_collision'>
          <pose frame=''>0 0 0 1.5707 -0 0</pose>
          <geometry>
            <cylinder>
              <length>0.168275</length>
              <radius>0.275</radius>
            </cylinder>
          </geometry>
          <max_contacts>10</max_contacts>
          <surface>
            <contact>
              <ode/>
            </contact>
            <bounce/>
            <friction>
              <torsional>
                <ode/>
              </torsional>
              <ode/>
            </friction>
          </surface>
        </collision>
        <visual name='left_rear_wheel_visual'>
          <pose frame=''>0 0 0 1.5707 -0 0</pose>
          <geometry>
            <mesh>
              <scale>0.12 0.12 0.12</scale>
              <uri>/home/csi/Workspace/SRC-Phase2/src/csi_rover_description/meshes/wheel.dae</uri>
            </mesh>
          </geometry>
        </visual>
        <self_collide>0</self_collide>
        <enable_wind>0</enable_wind>
        <kinematic>0</kinematic>
      </link>
      <joint name='left_rear_axle' type='revolute'>
        <child>left_rear_wheel</child>
        <parent>left_rear_axle_link</parent>
        <axis>
          <xyz>0 1 0</xyz>
          <limit>
            <lower>-1e+16</lower>
            <upper>1e+16</upper>
          </limit>
          <dynamics>
            <spring_reference>0</spring_reference>
            <spring_stiffness>0</spring_stiffness>
          </dynamics>
          <use_parent_model_frame>1</use_parent_model_frame>
        </axis>
      </joint>
      <link name='right_front_axle_link'>
        <pose frame=''>0.7874 -0.936625 0.106725 0 -0 0</pose>
        <inertial>
          <pose frame=''>0 0 0 0 -0 0</pose>
          <mass>0.001</mass>
          <inertia>
            <ixx>0.001</ixx>
            <ixy>0</ixy>
            <ixz>0</ixz>
            <iyy>0.001</iyy>
            <iyz>0</iyz>
            <izz>0.0001</izz>
          </inertia>
        </inertial>
        <visual name='right_front_axle_link_fixed_joint_lump__visual_visual'>
          <pose frame=''>0 0 0 3.14159 1.57079 -1.57089</pose>
          <geometry>
            <cylinder>
              <length>0.2</length>
              <radius>0.05</radius>
            </cylinder>
          </geometry>
        </visual>
        <self_collide>0</self_collide>
        <enable_wind>0</enable_wind>
        <kinematic>0</kinematic>
      </link>
      <joint name='right_front_steering_joint' type='revolute'>
        <child>right_front_axle_link</child>
        <parent>chassis</parent>
        <axis>
          <xyz>0 0 1</xyz>
          <limit>
            <lower>-1.5707</lower>
            <upper>1.5707</upper>
            <effort>10</effort>
            <velocity>15</velocity>
          </limit>
          <dynamics>
            <spring_reference>0</spring_reference>
            <spring_stiffness>0</spring_stiffness>
          </dynamics>
          <use_parent_model_frame>1</use_parent_model_frame>
        </axis>
      </joint>
      <link name='right_front_wheel'>
        <pose frame=''>0.7874 -0.936625 0.106725 0 -0 0</pose>
        <inertial>
          <pose frame=''>0 0 0 1.5707 -0 0</pose>
          <mass>2</mass>
          <inertia>
            <ixx>0.4</ixx>
            <ixy>0</ixy>
            <ixz>0</ixz>
            <iyy>0.4</iyy>
            <iyz>0</iyz>
            <izz>0.2</izz>
          </inertia>
        </inertial>
        <collision name='right_front_wheel_collision'>
          <pose frame=''>0 0 0 1.5707 -0 0</pose>
          <geometry>
            <cylinder>
              <length>0.168275</length>
              <radius>0.275</radius>
            </cylinder>
          </geometry>
          <max_contacts>10</max_contacts>
          <surface>
            <contact>
              <ode/>
            </contact>
            <bounce/>
            <friction>
              <torsional>
                <ode/>
              </torsional>
              <ode/>
            </friction>
          </surface>
        </collision>
        <visual name='right_front_wheel_visual'>
          <pose frame=''>0 0 0 1.5707 -0 0</pose>
          <geometry>
            <mesh>
              <scale>0.12 0.12 0.12</scale>
              <uri>/home/csi/Workspace/SRC-Phase2/src/csi_rover_description/meshes/wheel.dae</uri>
            </mesh>
          </geometry>
        </visual>
        <self_collide>0</self_collide>
        <enable_wind>0</enable_wind>
        <kinematic>0</kinematic>
      </link>
      <joint name='right_front_axle' type='revolute'>
        <child>right_front_wheel</child>
        <parent>right_front_axle_link</parent>
        <axis>
          <xyz>0 1 0</xyz>
          <limit>
            <lower>-1e+16</lower>
            <upper>1e+16</upper>
          </limit>
          <dynamics>
            <spring_reference>0</spring_reference>
            <spring_stiffness>0</spring_stiffness>
          </dynamics>
          <use_parent_model_frame>1</use_parent_model_frame>
        </axis>
      </joint>
      <link name='right_rear_axle_link'>
        <pose frame=''>-0.7874 -0.936625 0.106725 0 -0 0</pose>
        <inertial>
          <pose frame=''>0 0 0 0 -0 0</pose>
          <mass>0.001</mass>
          <inertia>
            <ixx>0.001</ixx>
            <ixy>0</ixy>
            <ixz>0</ixz>
            <iyy>0.001</iyy>
            <iyz>0</iyz>
            <izz>0.0001</izz>
          </inertia>
        </inertial>
        <visual name='right_rear_axle_link_fixed_joint_lump__visual_visual'>
          <pose frame=''>0 0 0 3.14159 1.57079 -1.57089</pose>
          <geometry>
            <cylinder>
              <length>0.2</length>
              <radius>0.05</radius>
            </cylinder>
          </geometry>
        </visual>
        <self_collide>0</self_collide>
        <enable_wind>0</enable_wind>
        <kinematic>0</kinematic>
      </link>
      <joint name='right_rear_steering_joint' type='revolute'>
        <child>right_rear_axle_link</child>
        <parent>chassis</parent>
        <axis>
          <xyz>0 0 1</xyz>
          <limit>
            <lower>-1.5707</lower>
            <upper>1.5707</upper>
            <effort>10</effort>
            <velocity>15</velocity>
          </limit>
          <dynamics>
            <spring_reference>0</spring_reference>
            <spring_stiffness>0</spring_stiffness>
          </dynamics>
          <use_parent_model_frame>1</use_parent_model_frame>
        </axis>
      </joint>
      <link name='right_rear_wheel'>
        <pose frame=''>-0.7874 -0.936625 0.106725 0 -0 0</pose>
        <inertial>
          <pose frame=''>0 0 0 1.5707 -0 0</pose>
          <mass>2</mass>
          <inertia>
            <ixx>0.4</ixx>
            <ixy>0</ixy>
            <ixz>0</ixz>
            <iyy>0.4</iyy>
            <iyz>0</iyz>
            <izz>0.2</izz>
          </inertia>
        </inertial>
        <collision name='right_rear_wheel_collision'>
          <pose frame=''>0 0 0 1.5707 -0 0</pose>
          <geometry>
            <cylinder>
              <length>0.168275</length>
              <radius>0.275</radius>
            </cylinder>
          </geometry>
          <max_contacts>10</max_contacts>
          <surface>
            <contact>
              <ode/>
            </contact>
            <bounce/>
            <friction>
              <torsional>
                <ode/>
              </torsional>
              <ode/>
            </friction>
          </surface>
        </collision>
        <visual name='right_rear_wheel_visual'>
          <pose frame=''>0 0 0 1.5707 -0 0</pose>
          <geometry>
            <mesh>
              <scale>0.12 0.12 0.12</scale>
              <uri>/home/csi/Workspace/SRC-Phase2/src/csi_rover_description/meshes/wheel.dae</uri>
            </mesh>
          </geometry>
        </visual>
        <self_collide>0</self_collide>
        <enable_wind>0</enable_wind>
        <kinematic>0</kinematic>
      </link>
      <joint name='right_rear_axle' type='revolute'>
        <child>right_rear_wheel</child>
        <parent>right_rear_axle_link</parent>
        <axis>
          <xyz>0 1 0</xyz>
          <limit>
            <lower>-1e+16</lower>
            <upper>1e+16</upper>
          </limit>
          <dynamics>
            <spring_reference>0</spring_reference>
            <spring_stiffness>0</spring_stiffness>
          </dynamics>
          <use_parent_model_frame>1</use_parent_model_frame>
        </axis>
      </joint>
      <plugin name='rover_odom' filename='librover_odom.so'>
        <updateRate>30.0</updateRate>
        <robotNamespace>/csi_rover</robotNamespace>
        <robotBaseFrame>chassis</robotBaseFrame>
        <odometryTopic>odom</odometryTopic>
        <odometryFrame>odom</odometryFrame>
      </plugin>
      <plugin name='p3d_base_controller' filename='libgazebo_ros_p3d.so'>
        <alwaysOn>1</alwaysOn>
        <updateRate>50.0</updateRate>
        <bodyName>chassis</bodyName>
        <topicName>/ground_truth</topicName>
        <gaussianNoise>0.01</gaussianNoise>
        <frameName>world</frameName>
        <xyzOffsets>0 0 0</xyzOffsets>
        <rpyOffsets>0 0 0</rpyOffsets>
        <robotNamespace>/</robotNamespace>
      </plugin>
      <static>0</static>
      <plugin name='gazebo_ros_control' filename='libgazebo_ros_control.so'>
        <robotNamespace>/csi_rover</robotNamespace>
        <robotSimType>gazebo_ros_control/DefaultRobotHWSim</robotSimType>
      </plugin>
      <pose frame=''>0 0 0 0 -0 0</pose>
    </model>
    <model name='Construction Cone'>
      <link name='link'>
        <collision name='collision'>
          <geometry>
            <mesh>
              <scale>10 10 10</scale>
              <uri>model://construction_cone/meshes/construction_cone.dae</uri>
            </mesh>
          </geometry>
          <max_contacts>10</max_contacts>
          <surface>
            <contact>
              <ode/>
            </contact>
            <bounce/>
            <friction>
              <torsional>
                <ode/>
              </torsional>
              <ode/>
            </friction>
          </surface>
        </collision>
        <visual name='visual'>
          <geometry>
            <mesh>
              <scale>10 10 10</scale>
              <uri>model://construction_cone/meshes/construction_cone.dae</uri>
            </mesh>
          </geometry>
        </visual>
        <self_collide>0</self_collide>
        <inertial>
          <inertia>
            <ixx>1</ixx>
            <ixy>0</ixy>
            <ixz>0</ixz>
            <iyy>1</iyy>
            <iyz>0</iyz>
            <izz>1</izz>
          </inertia>
          <mass>1</mass>
        </inertial>
        <enable_wind>0</enable_wind>
        <kinematic>0</kinematic>
      </link>
      <pose frame=''>2.37529 2.15637 0 0 -0 0</pose>
    </model>
    <model name='Construction Cone_0'>
      <link name='link'>
        <collision name='collision'>
          <geometry>
            <mesh>
              <scale>10 10 10</scale>
              <uri>model://construction_cone/meshes/construction_cone.dae</uri>
            </mesh>
          </geometry>
          <max_contacts>10</max_contacts>
          <surface>
            <contact>
              <ode/>
            </contact>
            <bounce/>
            <friction>
              <torsional>
                <ode/>
              </torsional>
              <ode/>
            </friction>
          </surface>
        </collision>
        <visual name='visual'>
          <geometry>
            <mesh>
              <scale>10 10 10</scale>
              <uri>model://construction_cone/meshes/construction_cone.dae</uri>
            </mesh>
          </geometry>
        </visual>
        <self_collide>0</self_collide>
        <inertial>
          <inertia>
            <ixx>1</ixx>
            <ixy>0</ixy>
            <ixz>0</ixz>
            <iyy>1</iyy>
            <iyz>0</iyz>
            <izz>1</izz>
          </inertia>
          <mass>1</mass>
        </inertial>
        <enable_wind>0</enable_wind>
        <kinematic>0</kinematic>
      </link>
      <pose frame=''>4.22861 2.37916 0 0 -0 0</pose>
    </model>
    <model name='Construction Cone_1'>
      <link name='link'>
        <collision name='collision'>
          <geometry>
            <mesh>
              <scale>10 10 10</scale>
              <uri>model://construction_cone/meshes/construction_cone.dae</uri>
            </mesh>
          </geometry>
          <max_contacts>10</max_contacts>
          <surface>
            <contact>
              <ode/>
            </contact>
            <bounce/>
            <friction>
              <torsional>
                <ode/>
              </torsional>
              <ode/>
            </friction>
          </surface>
        </collision>
        <visual name='visual'>
          <geometry>
            <mesh>
              <scale>10 10 10</scale>
              <uri>model://construction_cone/meshes/construction_cone.dae</uri>
            </mesh>
          </geometry>
        </visual>
        <self_collide>0</self_collide>
        <inertial>
          <inertia>
            <ixx>1</ixx>
            <ixy>0</ixy>
            <ixz>0</ixz>
            <iyy>1</iyy>
            <iyz>0</iyz>
            <izz>1</izz>
          </inertia>
          <mass>1</mass>
        </inertial>
        <enable_wind>0</enable_wind>
        <kinematic>0</kinematic>
      </link>
      <pose frame=''>6.02177 2.55047 0 0 -0 0</pose>
    </model>
    <model name='Construction Cone_2'>
      <link name='link'>
        <collision name='collision'>
          <geometry>
            <mesh>
              <scale>10 10 10</scale>
              <uri>model://construction_cone/meshes/construction_cone.dae</uri>
            </mesh>
          </geometry>
          <max_contacts>10</max_contacts>
          <surface>
            <contact>
              <ode/>
            </contact>
            <bounce/>
            <friction>
              <torsional>
                <ode/>
              </torsional>
              <ode/>
            </friction>
          </surface>
        </collision>
        <visual name='visual'>
          <geometry>
            <mesh>
              <scale>10 10 10</scale>
              <uri>model://construction_cone/meshes/construction_cone.dae</uri>
            </mesh>
          </geometry>
        </visual>
        <self_collide>0</self_collide>
        <inertial>
          <inertia>
            <ixx>1</ixx>
            <ixy>0</ixy>
            <ixz>0</ixz>
            <iyy>1</iyy>
            <iyz>0</iyz>
            <izz>1</izz>
          </inertia>
          <mass>1</mass>
        </inertial>
        <enable_wind>0</enable_wind>
        <kinematic>0</kinematic>
      </link>
      <pose frame=''>7.44045 3.65817 0 0 -0 0</pose>
    </model>
    <model name='Construction Cone_3'>
      <link name='link'>
        <collision name='collision'>
          <geometry>
            <mesh>
              <scale>10 10 10</scale>
              <uri>model://construction_cone/meshes/construction_cone.dae</uri>
            </mesh>
          </geometry>
          <max_contacts>10</max_contacts>
          <surface>
            <contact>
              <ode/>
            </contact>
            <bounce/>
            <friction>
              <torsional>
                <ode/>
              </torsional>
              <ode/>
            </friction>
          </surface>
        </collision>
        <visual name='visual'>
          <geometry>
            <mesh>
              <scale>10 10 10</scale>
              <uri>model://construction_cone/meshes/construction_cone.dae</uri>
            </mesh>
          </geometry>
        </visual>
        <self_collide>0</self_collide>
        <inertial>
          <inertia>
            <ixx>1</ixx>
            <ixy>0</ixy>
            <ixz>0</ixz>
            <iyy>1</iyy>
            <iyz>0</iyz>
            <izz>1</izz>
          </inertia>
          <mass>1</mass>
        </inertial>
        <enable_wind>0</enable_wind>
        <kinematic>0</kinematic>
      </link>
      <pose frame=''>8.58713 5.51528 0 0 -0 0</pose>
    </model>
    <model name='Construction Cone_4'>
      <link name='link'>
        <collision name='collision'>
          <geometry>
            <mesh>
              <scale>10 10 10</scale>
              <uri>model://construction_cone/meshes/construction_cone.dae</uri>
            </mesh>
          </geometry>
          <max_contacts>10</max_contacts>
          <surface>
            <contact>
              <ode/>
            </contact>
            <bounce/>
            <friction>
              <torsional>
                <ode/>
              </torsional>
              <ode/>
            </friction>
          </surface>
        </collision>
        <visual name='visual'>
          <geometry>
            <mesh>
              <scale>10 10 10</scale>
              <uri>model://construction_cone/meshes/construction_cone.dae</uri>
            </mesh>
          </geometry>
        </visual>
        <self_collide>0</self_collide>
        <inertial>
          <inertia>
            <ixx>1</ixx>
            <ixy>0</ixy>
            <ixz>0</ixz>
            <iyy>1</iyy>
            <iyz>0</iyz>
            <izz>1</izz>
          </inertia>
          <mass>1</mass>
        </inertial>
        <enable_wind>0</enable_wind>
        <kinematic>0</kinematic>
      </link>
      <pose frame=''>2.04462 -2.47301 0 0 -0 0</pose>
    </model>
    <model name='Construction Cone_5'>
      <link name='link'>
        <collision name='collision'>
          <geometry>
            <mesh>
              <scale>10 10 10</scale>
              <uri>model://construction_cone/meshes/construction_cone.dae</uri>
            </mesh>
          </geometry>
          <max_contacts>10</max_contacts>
          <surface>
            <contact>
              <ode/>
            </contact>
            <bounce/>
            <friction>
              <torsional>
                <ode/>
              </torsional>
              <ode/>
            </friction>
          </surface>
        </collision>
        <visual name='visual'>
          <geometry>
            <mesh>
              <scale>10 10 10</scale>
              <uri>model://construction_cone/meshes/construction_cone.dae</uri>
            </mesh>
          </geometry>
        </visual>
        <self_collide>0</self_collide>
        <inertial>
          <inertia>
            <ixx>1</ixx>
            <ixy>0</ixy>
            <ixz>0</ixz>
            <iyy>1</iyy>
            <iyz>0</iyz>
            <izz>1</izz>
          </inertia>
          <mass>1</mass>
        </inertial>
        <enable_wind>0</enable_wind>
        <kinematic>0</kinematic>
      </link>
      <pose frame=''>3.62926 -2.28363 0 0 -0 0</pose>
    </model>
    <model name='Construction Cone_6'>
      <link name='link'>
        <collision name='collision'>
          <geometry>
            <mesh>
              <scale>10 10 10</scale>
              <uri>model://construction_cone/meshes/construction_cone.dae</uri>
            </mesh>
          </geometry>
          <max_contacts>10</max_contacts>
          <surface>
            <contact>
              <ode/>
            </contact>
            <bounce/>
            <friction>
              <torsional>
                <ode/>
              </torsional>
              <ode/>
            </friction>
          </surface>
        </collision>
        <visual name='visual'>
          <geometry>
            <mesh>
              <scale>10 10 10</scale>
              <uri>model://construction_cone/meshes/construction_cone.dae</uri>
            </mesh>
          </geometry>
        </visual>
        <self_collide>0</self_collide>
        <inertial>
          <inertia>
            <ixx>1</ixx>
            <ixy>0</ixy>
            <ixz>0</ixz>
            <iyy>1</iyy>
            <iyz>0</iyz>
            <izz>1</izz>
          </inertia>
          <mass>1</mass>
        </inertial>
        <enable_wind>0</enable_wind>
        <kinematic>0</kinematic>
      </link>
      <pose frame=''>5.42296 -2.28467 0 0 -0 0</pose>
    </model>
    <model name='Construction Barrel'>
      <link name='link'>
        <inertial>
          <pose frame=''>0 0 0.4 0 -0 0</pose>
          <mass>500</mass>
          <inertia>
            <ixx>51.2096</ixx>
            <iyy>51.2096</iyy>
            <izz>25</izz>
            <ixy>0</ixy>
            <ixz>0</ixz>
            <iyz>0</iyz>
          </inertia>
        </inertial>
        <collision name='collision'>
          <geometry>
            <mesh>
              <uri>model://construction_barrel/meshes/construction_barrel.dae</uri>
            </mesh>
          </geometry>
          <max_contacts>10</max_contacts>
          <surface>
            <contact>
              <ode/>
            </contact>
            <bounce/>
            <friction>
              <torsional>
                <ode/>
              </torsional>
              <ode/>
            </friction>
          </surface>
        </collision>
        <visual name='visual'>
          <geometry>
            <mesh>
              <uri>model://construction_barrel/meshes/construction_barrel.dae</uri>
            </mesh>
          </geometry>
        </visual>
        <self_collide>0</self_collide>
        <enable_wind>0</enable_wind>
        <kinematic>0</kinematic>
      </link>
      <pose frame=''>7.43348 -1.80059 0 0 -0 0</pose>
    </model>
    <model name='Construction Barrel_0'>
      <link name='link'>
        <inertial>
          <pose frame=''>0 0 0.4 0 -0 0</pose>
          <mass>500</mass>
          <inertia>
            <ixx>51.2096</ixx>
            <iyy>51.2096</iyy>
            <izz>25</izz>
            <ixy>0</ixy>
            <ixz>0</ixz>
            <iyz>0</iyz>
          </inertia>
        </inertial>
        <collision name='collision'>
          <geometry>
            <mesh>
              <uri>model://construction_barrel/meshes/construction_barrel.dae</uri>
            </mesh>
          </geometry>
          <max_contacts>10</max_contacts>
          <surface>
            <contact>
              <ode/>
            </contact>
            <bounce/>
            <friction>
              <torsional>
                <ode/>
              </torsional>
              <ode/>
            </friction>
          </surface>
        </collision>
        <visual name='visual'>
          <geometry>
            <mesh>
              <uri>model://construction_barrel/meshes/construction_barrel.dae</uri>
            </mesh>
          </geometry>
        </visual>
        <self_collide>0</self_collide>
        <enable_wind>0</enable_wind>
        <kinematic>0</kinematic>
      </link>
      <pose frame=''>9.37852 0.03405 0 0 -0 0</pose>
    </model>
    <model name='Construction Cone_7'>
      <link name='link'>
        <collision name='collision'>
          <geometry>
            <mesh>
              <scale>10 10 10</scale>
              <uri>model://construction_cone/meshes/construction_cone.dae</uri>
            </mesh>
          </geometry>
          <max_contacts>10</max_contacts>
          <surface>
            <contact>
              <ode/>
            </contact>
            <bounce/>
            <friction>
              <torsional>
                <ode/>
              </torsional>
              <ode/>
            </friction>
          </surface>
        </collision>
        <visual name='visual'>
          <geometry>
            <mesh>
              <scale>10 10 10</scale>
              <uri>model://construction_cone/meshes/construction_cone.dae</uri>
            </mesh>
          </geometry>
        </visual>
        <self_collide>0</self_collide>
        <inertial>
          <inertia>
            <ixx>1</ixx>
            <ixy>0</ixy>
            <ixz>0</ixz>
            <iyy>1</iyy>
            <iyz>0</iyz>
            <izz>1</izz>
          </inertia>
          <mass>1</mass>
        </inertial>
        <enable_wind>0</enable_wind>
        <kinematic>0</kinematic>
      </link>
      <pose frame=''>11.1509 1.00726 0 0 -0 0</pose>
    </model>
    <model name='suv'>
      <static>1</static>
      <link name='link'>
        <collision name='collision'>
          <pose frame=''>0 0 0 0 0 -1.5708</pose>
          <geometry>
            <mesh>
              <scale>0.06 0.06 0.06</scale>
              <uri>model://suv/meshes/suv.obj</uri>
            </mesh>
          </geometry>
          <max_contacts>10</max_contacts>
          <surface>
            <contact>
              <ode/>
            </contact>
            <bounce/>
            <friction>
              <torsional>
                <ode/>
              </torsional>
              <ode/>
            </friction>
          </surface>
        </collision>
        <visual name='visual'>
          <pose frame=''>0 0 0 0 0 -1.5708</pose>
          <geometry>
            <mesh>
              <scale>0.06 0.06 0.06</scale>
              <uri>model://suv/meshes/suv.obj</uri>
            </mesh>
          </geometry>
        </visual>
        <self_collide>0</self_collide>
        <enable_wind>0</enable_wind>
        <kinematic>0</kinematic>
      </link>
      <pose frame=''>19.5164 6.53736 0 0 -0 0</pose>
    </model>
    <model name='bus'>
      <static>1</static>
      <link name='link'>
        <collision name='collision'>
          <geometry>
            <mesh>
              <scale>0.01 0.01 0.01</scale>
              <uri>model://bus/meshes/bus.obj</uri>
            </mesh>
          </geometry>
          <max_contacts>10</max_contacts>
          <surface>
            <contact>
              <ode/>
            </contact>
            <bounce/>
            <friction>
              <torsional>
                <ode/>
              </torsional>
              <ode/>
            </friction>
          </surface>
        </collision>
        <visual name='visual'>
          <geometry>
            <mesh>
              <scale>0.01 0.01 0.01</scale>
              <uri>model://bus/meshes/bus.obj</uri>
            </mesh>
          </geometry>
        </visual>
        <self_collide>0</self_collide>
        <enable_wind>0</enable_wind>
        <kinematic>0</kinematic>
      </link>
      <pose frame=''>-7.54767 16.1405 0 0 -0 0</pose>
    </model>
    <model name='apartment'>
      <static>1</static>
      <link name='link'>
        <collision name='collision'>
          <geometry>
            <mesh>
              <uri>model://apartment/meshes/apartment.dae</uri>
            </mesh>
          </geometry>
          <max_contacts>10</max_contacts>
          <surface>
            <contact>
              <ode/>
            </contact>
            <bounce/>
            <friction>
              <torsional>
                <ode/>
              </torsional>
              <ode/>
            </friction>
          </surface>
        </collision>
        <visual name='visual'>
          <geometry>
            <mesh>
              <uri>model://apartment/meshes/apartment.dae</uri>
            </mesh>
          </geometry>
        </visual>
        <self_collide>0</self_collide>
        <enable_wind>0</enable_wind>
        <kinematic>0</kinematic>
      </link>
      <pose frame=''>-25.2564 -19.6921 0 0 -0 0</pose>
    </model>
    <model name='Construction Cone_8'>
      <link name='link'>
        <collision name='collision'>
          <geometry>
            <mesh>
              <scale>10 10 10</scale>
              <uri>model://construction_cone/meshes/construction_cone.dae</uri>
            </mesh>
          </geometry>
          <max_contacts>10</max_contacts>
          <surface>
            <contact>
              <ode/>
            </contact>
            <bounce/>
            <friction>
              <torsional>
                <ode/>
              </torsional>
              <ode/>
            </friction>
          </surface>
        </collision>
        <visual name='visual'>
          <geometry>
            <mesh>
              <scale>10 10 10</scale>
              <uri>model://construction_cone/meshes/construction_cone.dae</uri>
            </mesh>
          </geometry>
        </visual>
        <self_collide>0</self_collide>
        <inertial>
          <inertia>
            <ixx>1</ixx>
            <ixy>0</ixy>
            <ixz>0</ixz>
            <iyy>1</iyy>
            <iyz>0</iyz>
            <izz>1</izz>
          </inertia>
          <mass>1</mass>
        </inertial>
        <enable_wind>0</enable_wind>
        <kinematic>0</kinematic>
      </link>
      <pose frame=''>12.6731 2.07176 0 0 -0 0</pose>
    </model>
    <model name='Construction Cone_9'>
      <link name='link'>
        <collision name='collision'>
          <geometry>
            <mesh>
              <scale>10 10 10</scale>
              <uri>model://construction_cone/meshes/construction_cone.dae</uri>
            </mesh>
          </geometry>
          <max_contacts>10</max_contacts>
          <surface>
            <contact>
              <ode/>
            </contact>
            <bounce/>
            <friction>
              <torsional>
                <ode/>
              </torsional>
              <ode/>
            </friction>
          </surface>
        </collision>
        <visual name='visual'>
          <geometry>
            <mesh>
              <scale>10 10 10</scale>
              <uri>model://construction_cone/meshes/construction_cone.dae</uri>
            </mesh>
          </geometry>
        </visual>
        <self_collide>0</self_collide>
        <inertial>
          <inertia>
            <ixx>1</ixx>
            <ixy>0</ixy>
            <ixz>0</ixz>
            <iyy>1</iyy>
            <iyz>0</iyz>
            <izz>1</izz>
          </inertia>
          <mass>1</mass>
        </inertial>
        <enable_wind>0</enable_wind>
        <kinematic>0</kinematic>
      </link>
      <pose frame=''>13.8392 3.46031 0 0 -0 0</pose>
    </model>
    <model name='Construction Cone_10'>
      <link name='link'>
        <collision name='collision'>
          <geometry>
            <mesh>
              <scale>10 10 10</scale>
              <uri>model://construction_cone/meshes/construction_cone.dae</uri>
            </mesh>
          </geometry>
          <max_contacts>10</max_contacts>
          <surface>
            <contact>
              <ode/>
            </contact>
            <bounce/>
            <friction>
              <torsional>
                <ode/>
              </torsional>
              <ode/>
            </friction>
          </surface>
        </collision>
        <visual name='visual'>
          <geometry>
            <mesh>
              <scale>10 10 10</scale>
              <uri>model://construction_cone/meshes/construction_cone.dae</uri>
            </mesh>
          </geometry>
        </visual>
        <self_collide>0</self_collide>
        <inertial>
          <inertia>
            <ixx>1</ixx>
            <ixy>0</ixy>
            <ixz>0</ixz>
            <iyy>1</iyy>
            <iyz>0</iyz>
            <izz>1</izz>
          </inertia>
          <mass>1</mass>
        </inertial>
        <enable_wind>0</enable_wind>
        <kinematic>0</kinematic>
      </link>
      <pose frame=''>8.3556 7.77605 0 0 -0 0</pose>
    </model>
    <model name='Construction Cone_11'>
      <link name='link'>
        <collision name='collision'>
          <geometry>
            <mesh>
              <scale>10 10 10</scale>
              <uri>model://construction_cone/meshes/construction_cone.dae</uri>
            </mesh>
          </geometry>
          <max_contacts>10</max_contacts>
          <surface>
            <contact>
              <ode/>
            </contact>
            <bounce/>
            <friction>
              <torsional>
                <ode/>
              </torsional>
              <ode/>
            </friction>
          </surface>
        </collision>
        <visual name='visual'>
          <geometry>
            <mesh>
              <scale>10 10 10</scale>
              <uri>model://construction_cone/meshes/construction_cone.dae</uri>
            </mesh>
          </geometry>
        </visual>
        <self_collide>0</self_collide>
        <inertial>
          <inertia>
            <ixx>1</ixx>
            <ixy>0</ixy>
            <ixz>0</ixz>
            <iyy>1</iyy>
            <iyz>0</iyz>
            <izz>1</izz>
          </inertia>
          <mass>1</mass>
        </inertial>
        <enable_wind>0</enable_wind>
        <kinematic>0</kinematic>
      </link>
      <pose frame=''>14.9835 4.97357 0 0 -0 0</pose>
    </model>
    <state world_name='default'>
      <sim_time>103 614000000</sim_time>
      <real_time>131 700685501</real_time>
      <wall_time>1583171288 997372769</wall_time>
      <iterations>103614</iterations>
      <model name='Construction Barrel'>
        <pose frame=''>7.4334 -1.80062 1e-06 3e-06 2e-06 -2.1e-05</pose>
        <scale>1 1 1</scale>
        <link name='link'>
          <pose frame=''>7.4334 -1.80062 1e-06 3e-06 2e-06 -2.1e-05</pose>
          <velocity>0 0 0 0 -0 0</velocity>
          <acceleration>-0.12752 6.72898 1.66267 2.0206 -0.390765 0.035239</acceleration>
          <wrench>-63.7599 3364.49 831.337 0 -0 0</wrench>
        </link>
      </model>
      <model name='Construction Barrel_0'>
        <pose frame=''>9.37843 -0.41133 -1e-06 2e-06 -2e-06 -1.8e-05</pose>
        <scale>1 1 1</scale>
        <link name='link'>
          <pose frame=''>9.37843 -0.41133 -1e-06 2e-06 -2e-06 -1.8e-05</pose>
          <velocity>0 0 0 0 -0 0</velocity>
          <acceleration>2.47438 -10.3729 8.78387 0.802554 -0.092453 -0.002377</acceleration>
          <wrench>1237.19 -5186.47 4391.93 0 -0 0</wrench>
        </link>
      </model>
      <model name='Construction Cone'>
        <pose frame=''>2.37529 2.15637 -0 0 -0 0</pose>
        <scale>1 1 1</scale>
        <link name='link'>
          <pose frame=''>2.37529 2.15637 -0 0 -0 0</pose>
          <velocity>0 0 0 0 -0 0</velocity>
          <acceleration>0 -0 -0.008512 -2.58585 1.13682 3.14159</acceleration>
          <wrench>0 -0 -0.008512 0 -0 0</wrench>
        </link>
      </model>
      <model name='Construction Cone_0'>
        <pose frame=''>4.22861 2.37916 -0 0 -0 0</pose>
        <scale>1 1 1</scale>
        <link name='link'>
          <pose frame=''>4.22861 2.37916 -0 0 -0 0</pose>
          <velocity>0 0 0 0 -0 0</velocity>
          <acceleration>0 -0 -0.008512 -2.58585 1.13682 3.14159</acceleration>
          <wrench>0 -0 -0.008512 0 -0 0</wrench>
        </link>
      </model>
      <model name='Construction Cone_1'>
        <pose frame=''>6.02177 2.55047 -0 0 -0 0</pose>
        <scale>1 1 1</scale>
        <link name='link'>
          <pose frame=''>6.02177 2.55047 -0 0 -0 0</pose>
          <velocity>0 0 0 0 -0 0</velocity>
          <acceleration>0 -0 -0.008512 -2.58585 1.13682 3.14159</acceleration>
          <wrench>0 -0 -0.008512 0 -0 0</wrench>
        </link>
      </model>
      <model name='Construction Cone_10'>
        <pose frame=''>8.3556 7.00859 -0 0 -1e-06 0</pose>
        <scale>1 1 1</scale>
        <link name='link'>
          <pose frame=''>8.3556 7.00859 -0 0 -1e-06 0</pose>
          <velocity>0 0 0 0 -0 0</velocity>
          <acceleration>-0 0 0.008512 2.58585 -1.13682 -3.14159</acceleration>
          <wrench>-0 0 0.008512 0 -0 0</wrench>
        </link>
      </model>
      <model name='Construction Cone_11'>
        <pose frame=''>14.9835 4.97357 -0 0 -0 0</pose>
        <scale>1 1 1</scale>
        <link name='link'>
          <pose frame=''>14.9835 4.97357 -0 0 -0 0</pose>
          <velocity>0 0 0 0 -0 0</velocity>
          <acceleration>-0 -1e-06 8.77172 -2.33085 -0.57167 -1e-06</acceleration>
          <wrench>-0 -1e-06 8.77172 0 -0 0</wrench>
        </link>
      </model>
      <model name='Construction Cone_2'>
        <pose frame=''>7.44045 3.65817 -0 0 -0 0</pose>
        <scale>1 1 1</scale>
        <link name='link'>
          <pose frame=''>7.44045 3.65817 -0 0 -0 0</pose>
          <velocity>0 0 0 0 -0 0</velocity>
          <acceleration>0 -0 -0.008512 -2.58585 1.13682 3.14159</acceleration>
          <wrench>0 -0 -0.008512 0 -0 0</wrench>
        </link>
      </model>
      <model name='Construction Cone_3'>
        <pose frame=''>8.58713 5.51528 -3e-06 -3e-06 -1e-06 -0</pose>
        <scale>1 1 1</scale>
        <link name='link'>
          <pose frame=''>8.58713 5.51528 -3e-06 -3e-06 -1e-06 -0</pose>
          <velocity>0 0 0 0 -0 0</velocity>
          <acceleration>0 0 -9.8 0 -0 0</acceleration>
          <wrench>0 0 -9.8 0 -0 0</wrench>
        </link>
      </model>
      <model name='Construction Cone_4'>
        <pose frame=''>2.04462 -2.47301 -4e-06 4e-06 -1e-06 0</pose>
        <scale>1 1 1</scale>
        <link name='link'>
          <pose frame=''>2.04462 -2.47301 -4e-06 4e-06 -1e-06 0</pose>
          <velocity>0 0 0 0 -0 0</velocity>
          <acceleration>0 0 -9.8 0 -0 0</acceleration>
          <wrench>0 0 -9.8 0 -0 0</wrench>
        </link>
      </model>
      <model name='Construction Cone_5'>
        <pose frame=''>3.62926 -2.28363 -1e-05 -1e-06 0 0</pose>
        <scale>1 1 1</scale>
        <link name='link'>
          <pose frame=''>3.62926 -2.28363 -1e-05 -1e-06 0 0</pose>
          <velocity>0 0 0 0 -0 0</velocity>
          <acceleration>0 0 -9.8 0 -0 0</acceleration>
          <wrench>0 0 -9.8 0 -0 0</wrench>
        </link>
      </model>
      <model name='Construction Cone_6'>
        <pose frame=''>5.42296 -2.28467 -1e-05 0 -0 0</pose>
        <scale>1 1 1</scale>
        <link name='link'>
          <pose frame=''>5.42296 -2.28467 -1e-05 0 -0 0</pose>
          <velocity>0 0 0 0 -0 0</velocity>
          <acceleration>0 0 -9.8 0 -0 0</acceleration>
          <wrench>0 0 -9.8 0 -0 0</wrench>
        </link>
      </model>
      <model name='Construction Cone_7'>
        <pose frame=''>11.1509 1.00726 -6e-06 -4e-06 0 0</pose>
        <scale>1 1 1</scale>
        <link name='link'>
          <pose frame=''>11.1509 1.00726 -6e-06 -4e-06 0 0</pose>
          <velocity>0 0 0 0 -0 0</velocity>
          <acceleration>0 0 -9.8 0 -0 0</acceleration>
          <wrench>0 0 -9.8 0 -0 0</wrench>
        </link>
      </model>
      <model name='Construction Cone_8'>
        <pose frame=''>12.6731 2.07176 -0 0 -0 0</pose>
        <scale>1 1 1</scale>
        <link name='link'>
          <pose frame=''>12.6731 2.07176 -0 0 -0 0</pose>
          <velocity>0 0 0 0 -0 0</velocity>
          <acceleration>0 -0 -0.008512 -2.58585 1.13682 3.14159</acceleration>
          <wrench>0 -0 -0.008512 0 -0 0</wrench>
        </link>
      </model>
      <model name='Construction Cone_9'>
        <pose frame=''>13.8392 3.46031 -0 0 -0 0</pose>
        <scale>1 1 1</scale>
        <link name='link'>
          <pose frame=''>13.8392 3.46031 -0 0 -0 0</pose>
          <velocity>0 0 0 0 -0 0</velocity>
          <acceleration>0 -0 -0.008512 -2.58585 1.13682 3.14159</acceleration>
          <wrench>0 -0 -0.008512 0 -0 0</wrench>
        </link>
      </model>
      <model name='apartment'>
        <pose frame=''>-20.7093 -17.0417 0 0 -0 0</pose>
        <scale>1 1 1</scale>
        <link name='link'>
          <pose frame=''>-20.7093 -17.0417 0 0 -0 0</pose>
          <velocity>0 0 0 0 -0 0</velocity>
          <acceleration>0 0 0 0 -0 0</acceleration>
          <wrench>0 0 0 0 -0 0</wrench>
        </link>
      </model>
      <model name='bus'>
        <pose frame=''>-7.54767 16.1405 0 0 -0 0</pose>
        <scale>1 1 1</scale>
        <link name='link'>
          <pose frame=''>-7.54767 16.1405 0 0 -0 0</pose>
          <velocity>0 0 0 0 -0 0</velocity>
          <acceleration>0 0 0 0 -0 0</acceleration>
          <wrench>0 0 0 0 -0 0</wrench>
        </link>
      </model>
      <model name='csi_rover'>
        <pose frame=''>0.335592 -0.032579 0.167718 6.3e-05 3.9e-05 0.047158</pose>
        <scale>1 1 1</scale>
        <link name='chassis'>
          <pose frame=''>0.335592 -0.032579 0.167718 6.3e-05 3.9e-05 0.047158</pose>
          <velocity>9.5e-05 0.000417 -2.2e-05 0.001617 -0.000483 0.000308</velocity>
          <acceleration>-0.020332 -0.037826 0.246733 0.076817 0.982789 -2.55344</acceleration>
          <wrench>-0.170872 -0.317893 2.07354 0 -0 0</wrench>
        </link>
        <link name='left_front_axle_link'>
          <pose frame=''>1.07794 0.9401 0.275228 9.9e-05 3.9e-05 0.047271</pose>
          <velocity>-0.00028 -0.000381 0.013389 6.9e-05 -0.000542 -7e-06</velocity>
          <acceleration>-0.271024 0.025127 27.7774 -3.07202 1.24333 -2.87554</acceleration>
          <wrench>-0.000271 2.5e-05 0.027777 0 -0 0</wrench>
        </link>
        <link name='left_front_wheel'>
          <pose frame=''>1.07795 0.940103 0.275 9.7e-05 0.418674 0.04731</pose>
          <velocity>-0.000263 -0.000156 0.009999 0.000567 -0.000957 -6e-06</velocity>
          <acceleration>-0.496155 0.297293 20.0134 0.882214 1.31793 0.020062</acceleration>
          <wrench>-0.992311 0.594586 40.0267 0 -0 0</wrench>
        </link>
        <link name='left_rear_axle_link'>
          <pose frame=''>-0.49502 0.86585 0.275208 0.000116 4.2e-05 0.046873</pose>
          <velocity>0.0004 -0.001052 0.013525 0.003392 -0.000352 -0.000107</velocity>
          <acceleration>1.3059 0.102245 26.2505 -0.520107 0.993368 2.9141</acceleration>
          <wrench>0.001306 0.000102 0.026251 0 -0 0</wrench>
        </link>
        <link name='left_rear_wheel'>
          <pose frame=''>-0.495036 0.865858 0.275 9.6e-05 -0.167029 0.046857</pose>
          <velocity>0.000251 -0.000761 0.009747 0.002766 0.000918 -8.9e-05</velocity>
          <acceleration>0.671195 0.180016 19.7002 -0.2669 -1.2684 -2.99338</acceleration>
          <wrench>1.34239 0.360032 39.4005 0 -0 0</wrench>
        </link>
        <link name='right_front_axle_link'>
          <pose frame=''>1.16621 -0.931043 0.275266 9.3e-05 3.9e-05 0.047158</pose>
          <velocity>-0.000453 6e-06 0.001691 -0.000897 -0.000594 -8.9e-05</velocity>
          <acceleration>0.245159 -2.13843 3.30861 2.75706 0.893508 -2.27348</acceleration>
          <wrench>0.000245 -0.002138 0.003309 0 -0 0</wrench>
        </link>
        <link name='right_front_wheel'>
          <pose frame=''>1.16623 -0.931048 0.275001 8.9e-05 0.572177 0.047206</pose>
          <velocity>-0.00025 7.1e-05 0.001009 -0.000259 -0.000888 -7.9e-05</velocity>
          <acceleration>0.04712 -1.32835 1.4138 -1.50818 0.150963 0.510919</acceleration>
          <wrench>0.09424 -2.65671 2.82761 0 -0 0</wrench>
        </link>
        <link name='right_rear_axle_link'>
          <pose frame=''>-0.406788 -1.00529 0.274183 2.8e-05 4.2e-05 0.047159</pose>
          <velocity>0.000456 3.9e-05 -0.006725 0.001659 -0.000467 -4.4e-05</velocity>
          <acceleration>-0.528396 0.737696 -12.7828 -1.87185 1.13989 3.06622</acceleration>
          <wrench>-0.000528 0.000738 -0.012783 0 -0 0</wrench>
        </link>
        <link name='right_rear_wheel'>
          <pose frame=''>-0.406741 -1.00528 0.275 9.6e-05 -0.153348 0.047145</pose>
          <velocity>0.000145 -5.7e-05 0.010024 0.000206 0.000528 -3.8e-05</velocity>
          <acceleration>0.653712 -0.079611 28.9236 0.779872 -1.42986 -3.1169</acceleration>
          <wrench>1.30742 -0.159221 57.8472 0 -0 0</wrench>
        </link>
      </model>
      <model name='ground_plane'>
        <pose frame=''>0 0 0 0 -0 0</pose>
        <scale>1 1 1</scale>
        <link name='link'>
          <pose frame=''>0 0 0 0 -0 0</pose>
          <velocity>0 0 0 0 -0 0</velocity>
          <acceleration>0 0 0 0 -0 0</acceleration>
          <wrench>0 0 0 0 -0 0</wrench>
        </link>
      </model>
      <model name='suv'>
        <pose frame=''>19.5164 6.53736 0 0 -0 0</pose>
        <scale>1 1 1</scale>
        <link name='link'>
          <pose frame=''>19.5164 6.53736 0 0 -0 0</pose>
          <velocity>0 0 0 0 -0 0</velocity>
          <acceleration>0 0 0 0 -0 0</acceleration>
          <wrench>0 0 0 0 -0 0</wrench>
        </link>
      </model>
      <light name='sun'>
        <pose frame=''>0 0 10 0 -0 0</pose>
      </light>
    </state>
    <gui fullscreen='0'>
      <camera name='user_camera'>
        <pose frame=''>-29.3868 3.41982 8.40854 0 0.067643 -0.211805</pose>
        <view_controller>orbit</view_controller>
        <projection_type>perspective</projection_type>
      </camera>
    </gui>
  </world>
</sdf>
