<sdf version='1.6'>
  <world name='moon'>
    <light name='sun' type='directional'>
      <cast_shadows>1</cast_shadows>
      <pose frame=''>0 0 10 0 -0 0</pose>
      <diffuse>0.8 0.8 0.8 1</diffuse>
      <specular>0.2 0.2 0.2 1</specular>
      <attenuation>
        <range>1000</range>
        <constant>0.9</constant>
        <linear>0.01</linear>
        <quadratic>0.001</quadratic>
      </attenuation>
      <direction>-0.5 0.1 -0.9</direction>
    </light>
    <model name='apollo15_landing_site_1000x1000'>
      <static>1</static>
      <link name='link'>
        <collision name='collision'>
          <surface>
            <friction>
              <ode>
                <mu>0.2</mu>
              </ode>
              <torsional>
                <ode/>
              </torsional>
            </friction>
            <contact>
              <ode>
                <soft_cfm>1</soft_cfm>
                <kp>100000</kp>
                <kd>1</kd>
                <max_vel>1e-06</max_vel>
                <min_depth>0.02</min_depth>
              </ode>
            </contact>
            <bounce/>
          </surface>
          <geometry>
            <heightmap>
              <uri>model://apollo15_landing_site_1000x1000/materials/textures/NAC_DTM_APOLLO15_E261N0036_257x257+7472+2152.png</uri>
              <size>514 514 49</size>
              <pos>0 0 -45</pos>
              <texture>
                <size>10</size>
                <diffuse>__default__</diffuse>
                <normal>__default__</normal>
              </texture>
              <blend>
                <min_height>0</min_height>
                <fade_dist>0</fade_dist>
              </blend>
            </heightmap>
          </geometry>
          <max_contacts>10</max_contacts>
        </collision>
        <visual name='visual'>
          <geometry>
            <heightmap>
              <texture>
                <diffuse>model://apollo15_landing_site_1000x1000/materials/textures/AS16-110-18026HR-512x512.jpg</diffuse>
                <normal>file://media/materials/textures/flat_normal.png</normal>
                <size>2</size>
              </texture>
              <uri>model://apollo15_landing_site_1000x1000/materials/textures/NAC_DTM_APOLLO15_E261N0036_257x257+7472+2152.png</uri>
              <size>514 514 49</size>
              <pos>0 0 -45</pos>
              <blend>
                <min_height>0</min_height>
                <fade_dist>0</fade_dist>
              </blend>
            </heightmap>
          </geometry>
        </visual>
        <self_collide>0</self_collide>
        <enable_wind>0</enable_wind>
        <kinematic>0</kinematic>
      </link>
    </model>
    <physics name='default_physics' default='0' type='ode'>
      <max_step_size>0.01</max_step_size>
      <real_time_factor>1</real_time_factor>
      <real_time_update_rate>100</real_time_update_rate>
    </physics>
    <gravity>0 0 -1.622</gravity>
    <magnetic_field>6e-06 2.3e-05 -4.2e-05</magnetic_field>
    <atmosphere type='adiabatic'/>
    <scene>
      <ambient>0.4 0.4 0.4 1</ambient>
      <background>0.7 0.7 0.7 1</background>
      <shadows>1</shadows>
    </scene>
    <audio>
      <device>default</device>
    </audio>
    <wind/>
    <spherical_coordinates>
      <surface_model>EARTH_WGS84</surface_model>
      <latitude_deg>0</latitude_deg>
      <longitude_deg>0</longitude_deg>
      <elevation>0</elevation>
      <heading_deg>0</heading_deg>
    </spherical_coordinates>
    <model name='csi_rover'>
      <link name='chassis'>
        <pose frame=''>0 0 0 0 -0 0</pose>
        <inertial>
          <pose frame=''>0.03653 0 0.465831 0 -0 0</pose>
          <mass>8.40401</mass>
          <inertia>
            <ixx>0.0391404</ixx>
            <ixy>7.92122e-21</ixy>
            <ixz>-0.0488739</ixz>
            <iyy>0.27282</iyy>
            <iyz>1.01011e-19</iyz>
            <izz>0.267518</izz>
          </inertia>
        </inertial>
        <collision name='chassis_fixed_joint_lump__collision_collision'>
          <pose frame=''>0 0 0.4572 0 -0 0</pose>
          <geometry>
            <box>
              <size>0.75 0.625 0.0889</size>
            </box>
          </geometry>
          <max_contacts>10</max_contacts>
          <surface>
            <contact>
              <ode/>
            </contact>
            <bounce/>
            <friction>
              <torsional>
                <ode/>
              </torsional>
              <ode/>
            </friction>
          </surface>
        </collision>
        <collision name='chassis_fixed_joint_lump__imu_link_collision_1'>
          <pose frame=''>0.4 0 0.712 0 -0 0</pose>
          <geometry>
            <box>
              <size>0.08 0.08 0.08</size>
            </box>
          </geometry>
          <surface>
            <contact>
              <ode/>
            </contact>
            <friction>
              <ode/>
              <torsional>
                <ode/>
              </torsional>
            </friction>
            <bounce/>
          </surface>
          <max_contacts>10</max_contacts>
        </collision>
        <collision name='chassis_fixed_joint_lump__lidar_link_collision_2'>
          <pose frame=''>0 0 0.862 0 -0 0</pose>
          <geometry>
            <box>
              <size>0.1 0.1 0.1</size>
            </box>
          </geometry>
          <surface>
            <contact>
              <ode/>
            </contact>
            <friction>
              <ode/>
              <torsional>
                <ode/>
              </torsional>
            </friction>
            <bounce/>
          </surface>
          <max_contacts>10</max_contacts>
        </collision>
        <collision name='chassis_fixed_joint_lump__main_camera_link_collision_3'>
          <pose frame=''>0.85 0 0.612 0 -0 0</pose>
          <geometry>
            <box>
              <size>0.08 0.08 0.08</size>
            </box>
          </geometry>
          <max_contacts>10</max_contacts>
          <surface>
            <contact>
              <ode/>
            </contact>
            <bounce/>
            <friction>
              <torsional>
                <ode/>
              </torsional>
              <ode/>
            </friction>
          </surface>
        </collision>
        <collision name='chassis_fixed_joint_lump__left_camera_link_collision_4'>
          <pose frame=''>0.91 0.2 0.612 0 -0 0</pose>
          <geometry>
            <box>
              <size>0.08 0.08 0.08</size>
            </box>
          </geometry>
          <surface>
            <contact>
              <ode/>
            </contact>
            <friction>
              <ode/>
              <torsional>
                <ode/>
              </torsional>
            </friction>
            <bounce/>
          </surface>
          <max_contacts>10</max_contacts>
        </collision>
        <collision name='chassis_fixed_joint_lump__right_camera_link_collision_5'>
          <pose frame=''>0.91 -0.2 0.612 0 -0 0</pose>
          <geometry>
            <box>
              <size>0.08 0.08 0.08</size>
            </box>
          </geometry>
          <max_contacts>10</max_contacts>
          <surface>
            <contact>
              <ode/>
            </contact>
            <bounce/>
            <friction>
              <torsional>
                <ode/>
              </torsional>
              <ode/>
            </friction>
          </surface>
        </collision>
        <visual name='chassis_fixed_joint_lump__visual_visual'>
          <pose frame=''>0 0 0.4572 0 -0 0</pose>
          <geometry>
            <mesh>
              <scale>0.15 0.15 0.15</scale>
              <uri>/home/csi/Workspace/SRC-Phase2/src/csi_rover_description/meshes/robot_body.dae</uri>
            </mesh>
          </geometry>
        </visual>
        <visual name='chassis_fixed_joint_lump__imu_link_visual_1'>
          <pose frame=''>0.4 0 0.712 0 -0 0</pose>
          <geometry>
            <box>
              <size>0.08 0.08 0.08</size>
            </box>
          </geometry>
          <material>
            <script>
              <uri>__default__</uri>
              <name>__default__</name>
            </script>
          </material>
        </visual>
        <visual name='chassis_fixed_joint_lump__visual_visual_2'>
          <pose frame=''>0.7862 0.92845 0.6096 0 -0 0</pose>
          <geometry>
            <box>
              <size>0.75 0.15625 0.0889</size>
            </box>
          </geometry>
        </visual>
        <visual name='chassis_fixed_joint_lump__visual_visual_3'>
          <pose frame=''>-0.7862 0.92845 0.6096 0 -0 0</pose>
          <geometry>
            <box>
              <size>0.75 0.15625 0.0889</size>
            </box>
          </geometry>
        </visual>
        <visual name='chassis_fixed_joint_lump__lidar_link_visual_4'>
          <pose frame=''>0 0 0.862 0 -0 0</pose>
          <geometry>
            <mesh>
              <scale>2 2 2</scale>
              <uri>/home/csi/Workspace/SRC-Phase2/src/csi_rover_description/meshes/hokuyo.dae</uri>
            </mesh>
          </geometry>
          <material>
            <script>
              <uri>__default__</uri>
              <name>__default__</name>
            </script>
          </material>
        </visual>
        <visual name='chassis_fixed_joint_lump__main_camera_link_visual_5'>
          <pose frame=''>0.85 0 0.612 0 -0 0</pose>
          <geometry>
            <mesh>
              <scale>0.006 0.006 0.006</scale>
              <uri>/home/csi/Workspace/SRC-Phase2/src/csi_rover_description/meshes/camera.dae</uri>
            </mesh>
          </geometry>
        </visual>
        <visual name='chassis_fixed_joint_lump__left_camera_link_visual_6'>
          <pose frame=''>0.91 0.2 0.612 0 -0 0</pose>
          <geometry>
            <box>
              <size>0.08 0.08 0.08</size>
            </box>
          </geometry>
          <material>
            <script>
              <uri>__default__</uri>
              <name>__default__</name>
            </script>
          </material>
        </visual>
        <visual name='chassis_fixed_joint_lump__right_camera_link_visual_7'>
          <pose frame=''>0.91 -0.2 0.612 0 -0 0</pose>
          <geometry>
            <box>
              <size>0.08 0.08 0.08</size>
            </box>
          </geometry>
        </visual>
        <visual name='chassis_fixed_joint_lump__visual_visual_8'>
          <pose frame=''>0.7862 -0.92845 0.6096 0 -0 0</pose>
          <geometry>
            <box>
              <size>0.75 0.15625 0.0889</size>
            </box>
          </geometry>
        </visual>
        <visual name='chassis_fixed_joint_lump__visual_visual_9'>
          <pose frame=''>-0.7862 -0.92845 0.6096 0 -0 0</pose>
          <geometry>
            <box>
              <size>0.75 0.15625 0.0889</size>
            </box>
          </geometry>
        </visual>
        <velocity_decay/>
        <velocity_decay/>
        <sensor name='imu_sensor' type='imu'>
          <always_on>1</always_on>
          <update_rate>100</update_rate>
          <visualize>1</visualize>
          <plugin name='imu_plugin' filename='libgazebo_ros_imu_sensor.so'>
            <robotNamespace>/csi_rover</robotNamespace>
            <topicName>imu</topicName>
            <bodyName>imu_link</bodyName>
            <updateRateHZ>30.0</updateRateHZ>
            <gaussianNoise>0.0</gaussianNoise>
            <xyzOffset>0 0 0</xyzOffset>
            <rpyOffset>0 0 0</rpyOffset>
            <frameName>imu_link</frameName>
          </plugin>
          <pose frame=''>0.4 0 -0.05 0 -0 0</pose>
          <imu/>
        </sensor>
        <gravity>1</gravity>
        <velocity_decay/>
        <sensor name='head_hokuyo_sensor' type='gpu_ray'>
          <visualize>1</visualize>
          <update_rate>40</update_rate>
          <ray>
            <scan>
              <horizontal>
                <samples>720</samples>
                <resolution>1</resolution>
                <min_angle>-2</min_angle>
                <max_angle>2</max_angle>
              </horizontal>
            </scan>
            <range>
              <min>0.1</min>
              <max>30</max>
              <resolution>0.01</resolution>
            </range>
            <noise>
              <type>gaussian</type>
              <mean>0</mean>
              <stddev>0.01</stddev>
            </noise>
          </ray>
          <plugin name='gazebo_ros_head_hokuyo_controller' filename='libgazebo_ros_gpu_laser.so'>
            <topicName>/csi_rover/laser/scan</topicName>
            <frameName>lidar_link</frameName>
            <robotNamespace>/</robotNamespace>
          </plugin>
          <pose frame=''>0 0 0.862 0 -0 0</pose>
        </sensor>
        <gravity>1</gravity>
        <velocity_decay/>
        <sensor name='stereo_camera' type='multicamera'>
          <update_rate>30</update_rate>
          <camera name='left'>
            <horizontal_fov>1.22173</horizontal_fov>
            <image>
              <width>1920</width>
              <height>1080</height>
              <format>R8G8B8</format>
            </image>
            <clip>
              <near>0.02</near>
              <far>300</far>
            </clip>
            <noise>
              <type>gaussian</type>
              <mean>0</mean>
              <stddev>0.007</stddev>
            </noise>
          </camera>
          <camera name='right'>
            <pose frame=''>0 -0.4 0 0 -0 0</pose>
            <horizontal_fov>1.22173</horizontal_fov>
            <image>
              <width>1920</width>
              <height>1080</height>
              <format>R8G8B8</format>
            </image>
            <clip>
              <near>0.02</near>
              <far>300</far>
            </clip>
            <noise>
              <type>gaussian</type>
              <mean>0</mean>
              <stddev>0.007</stddev>
            </noise>
          </camera>
          <plugin name='stereo_camera_controller' filename='libgazebo_ros_multicamera.so'>
            <alwaysOn>1</alwaysOn>
            <updateRate>0.0</updateRate>
            <cameraName>csi_rover/camera</cameraName>
            <imageTopicName>image_raw</imageTopicName>
            <cameraInfoTopicName>camera_info</cameraInfoTopicName>
            <frameName>left_camera_link</frameName>
            <rightFrameName>right_camera_link</rightFrameName>
            <hackBaseline>0.07</hackBaseline>
            <distortionK1>0.0</distortionK1>
            <distortionK2>0.0</distortionK2>
            <distortionK3>0.0</distortionK3>
            <distortionT1>0.0</distortionT1>
            <distortionT2>0.0</distortionT2>
            <robotNamespace>/</robotNamespace>
          </plugin>
          <pose frame=''>0.91 0.2 0.612 0 -0 0</pose>
        </sensor>
        <self_collide>0</self_collide>
        <enable_wind>0</enable_wind>
        <kinematic>0</kinematic>
      </link>
      <link name='left_front_axle_link'>
        <pose frame=''>0.7862 0.92845 0.2159 0 -0 0</pose>
        <inertial>
          <pose frame=''>0 0 0 0 -0 0</pose>
          <mass>0.001</mass>
          <inertia>
            <ixx>0.001</ixx>
            <ixy>0</ixy>
            <ixz>0</ixz>
            <iyy>0.001</iyy>
            <iyz>0</iyz>
            <izz>0.0001</izz>
          </inertia>
        </inertial>
        <visual name='left_front_axle_link_fixed_joint_lump__visual_visual'>
          <pose frame=''>0 0 0 3.14159 1.57079 -1.57089</pose>
          <geometry>
            <cylinder>
              <length>0.2</length>
              <radius>0.05</radius>
            </cylinder>
          </geometry>
        </visual>
        <self_collide>0</self_collide>
        <enable_wind>0</enable_wind>
        <kinematic>0</kinematic>
      </link>
      <joint name='left_front_steering_joint' type='revolute'>
        <child>left_front_axle_link</child>
        <parent>chassis</parent>
        <axis>
          <xyz>0 0 1</xyz>
          <limit>
            <lower>-1.5707</lower>
            <upper>1.5707</upper>
            <effort>10</effort>
            <velocity>15</velocity>
          </limit>
          <dynamics>
            <spring_reference>0</spring_reference>
            <spring_stiffness>0</spring_stiffness>
          </dynamics>
          <use_parent_model_frame>1</use_parent_model_frame>
        </axis>
      </joint>
      <link name='left_front_wheel'>
        <pose frame=''>0.7862 0.92845 0.2159 0 -0 0</pose>
        <inertial>
          <pose frame=''>0 0 0 1.5707 -0 0</pose>
          <mass>2</mass>
          <inertia>
            <ixx>0.4</ixx>
            <ixy>0</ixy>
            <ixz>0</ixz>
            <iyy>0.4</iyy>
            <iyz>0</iyz>
            <izz>0.2</izz>
          </inertia>
        </inertial>
        <collision name='left_front_wheel_collision'>
          <pose frame=''>0 0 0 1.5707 -0 0</pose>
          <geometry>
            <cylinder>
              <length>0.0889</length>
              <radius>0.3048</radius>
            </cylinder>
          </geometry>
          <max_contacts>10</max_contacts>
          <surface>
            <contact>
              <ode/>
            </contact>
            <bounce/>
            <friction>
              <torsional>
                <ode/>
              </torsional>
              <ode/>
            </friction>
          </surface>
        </collision>
        <visual name='left_front_wheel_visual'>
          <pose frame=''>0 0 0 1.5707 -0 0</pose>
          <geometry>
            <mesh>
              <scale>0.12 0.12 0.12</scale>
              <uri>/home/csi/Workspace/SRC-Phase2/src/csi_rover_description/meshes/wheel.dae</uri>
            </mesh>
          </geometry>
        </visual>
        <self_collide>0</self_collide>
        <enable_wind>0</enable_wind>
        <kinematic>0</kinematic>
      </link>
      <joint name='left_front_axle' type='revolute'>
        <child>left_front_wheel</child>
        <parent>left_front_axle_link</parent>
        <axis>
          <xyz>0 1 0</xyz>
          <limit>
            <lower>-1e+16</lower>
            <upper>1e+16</upper>
          </limit>
          <dynamics>
            <spring_reference>0</spring_reference>
            <spring_stiffness>0</spring_stiffness>
          </dynamics>
          <use_parent_model_frame>1</use_parent_model_frame>
        </axis>
      </joint>
      <link name='left_rear_axle_link'>
        <pose frame=''>-0.7862 0.92845 0.2159 0 -0 0</pose>
        <inertial>
          <pose frame=''>0 0 0 0 -0 0</pose>
          <mass>0.001</mass>
          <inertia>
            <ixx>0.001</ixx>
            <ixy>0</ixy>
            <ixz>0</ixz>
            <iyy>0.001</iyy>
            <iyz>0</iyz>
            <izz>0.0001</izz>
          </inertia>
        </inertial>
        <visual name='left_rear_axle_link_fixed_joint_lump__visual_visual'>
          <pose frame=''>0 0 0 3.14159 1.57079 -1.57089</pose>
          <geometry>
            <cylinder>
              <length>0.2</length>
              <radius>0.05</radius>
            </cylinder>
          </geometry>
        </visual>
        <self_collide>0</self_collide>
        <enable_wind>0</enable_wind>
        <kinematic>0</kinematic>
      </link>
      <joint name='left_rear_steering_joint' type='revolute'>
        <child>left_rear_axle_link</child>
        <parent>chassis</parent>
        <axis>
          <xyz>0 0 1</xyz>
          <limit>
            <lower>-1.5707</lower>
            <upper>1.5707</upper>
            <effort>10</effort>
            <velocity>15</velocity>
          </limit>
          <dynamics>
            <spring_reference>0</spring_reference>
            <spring_stiffness>0</spring_stiffness>
          </dynamics>
          <use_parent_model_frame>1</use_parent_model_frame>
        </axis>
      </joint>
      <link name='left_rear_wheel'>
        <pose frame=''>-0.7862 0.92845 0.2159 0 -0 0</pose>
        <inertial>
          <pose frame=''>0 0 0 1.5707 -0 0</pose>
          <mass>2</mass>
          <inertia>
            <ixx>0.4</ixx>
            <ixy>0</ixy>
            <ixz>0</ixz>
            <iyy>0.4</iyy>
            <iyz>0</iyz>
            <izz>0.2</izz>
          </inertia>
        </inertial>
        <collision name='left_rear_wheel_collision'>
          <pose frame=''>0 0 0 1.5707 -0 0</pose>
          <geometry>
            <cylinder>
              <length>0.0889</length>
              <radius>0.3048</radius>
            </cylinder>
          </geometry>
          <max_contacts>10</max_contacts>
          <surface>
            <contact>
              <ode/>
            </contact>
            <bounce/>
            <friction>
              <torsional>
                <ode/>
              </torsional>
              <ode/>
            </friction>
          </surface>
        </collision>
        <visual name='left_rear_wheel_visual'>
          <pose frame=''>0 0 0 1.5707 -0 0</pose>
          <geometry>
            <mesh>
              <scale>0.12 0.12 0.12</scale>
              <uri>/home/csi/Workspace/SRC-Phase2/src/csi_rover_description/meshes/wheel.dae</uri>
            </mesh>
          </geometry>
        </visual>
        <self_collide>0</self_collide>
        <enable_wind>0</enable_wind>
        <kinematic>0</kinematic>
      </link>
      <joint name='left_rear_axle' type='revolute'>
        <child>left_rear_wheel</child>
        <parent>left_rear_axle_link</parent>
        <axis>
          <xyz>0 1 0</xyz>
          <limit>
            <lower>-1e+16</lower>
            <upper>1e+16</upper>
          </limit>
          <dynamics>
            <spring_reference>0</spring_reference>
            <spring_stiffness>0</spring_stiffness>
          </dynamics>
          <use_parent_model_frame>1</use_parent_model_frame>
        </axis>
      </joint>
      <link name='right_front_axle_link'>
        <pose frame=''>0.7862 -0.92845 0.2159 0 -0 0</pose>
        <inertial>
          <pose frame=''>0 0 0 0 -0 0</pose>
          <mass>0.001</mass>
          <inertia>
            <ixx>0.001</ixx>
            <ixy>0</ixy>
            <ixz>0</ixz>
            <iyy>0.001</iyy>
            <iyz>0</iyz>
            <izz>0.0001</izz>
          </inertia>
        </inertial>
        <visual name='right_front_axle_link_fixed_joint_lump__visual_visual'>
          <pose frame=''>0 0 0 3.14159 1.57079 -1.57089</pose>
          <geometry>
            <cylinder>
              <length>0.2</length>
              <radius>0.05</radius>
            </cylinder>
          </geometry>
        </visual>
        <self_collide>0</self_collide>
        <enable_wind>0</enable_wind>
        <kinematic>0</kinematic>
      </link>
      <joint name='right_front_steering_joint' type='revolute'>
        <child>right_front_axle_link</child>
        <parent>chassis</parent>
        <axis>
          <xyz>0 0 1</xyz>
          <limit>
            <lower>-1.5707</lower>
            <upper>1.5707</upper>
            <effort>10</effort>
            <velocity>15</velocity>
          </limit>
          <dynamics>
            <spring_reference>0</spring_reference>
            <spring_stiffness>0</spring_stiffness>
          </dynamics>
          <use_parent_model_frame>1</use_parent_model_frame>
        </axis>
      </joint>
      <link name='right_front_wheel'>
        <pose frame=''>0.7862 -0.92845 0.2159 0 -0 0</pose>
        <inertial>
          <pose frame=''>0 0 0 1.5707 -0 0</pose>
          <mass>2</mass>
          <inertia>
            <ixx>0.4</ixx>
            <ixy>0</ixy>
            <ixz>0</ixz>
            <iyy>0.4</iyy>
            <iyz>0</iyz>
            <izz>0.2</izz>
          </inertia>
        </inertial>
        <collision name='right_front_wheel_collision'>
          <pose frame=''>0 0 0 1.5707 -0 0</pose>
          <geometry>
            <cylinder>
              <length>0.0889</length>
              <radius>0.3048</radius>
            </cylinder>
          </geometry>
          <max_contacts>10</max_contacts>
          <surface>
            <contact>
              <ode/>
            </contact>
            <bounce/>
            <friction>
              <torsional>
                <ode/>
              </torsional>
              <ode/>
            </friction>
          </surface>
        </collision>
        <visual name='right_front_wheel_visual'>
          <pose frame=''>0 0 0 1.5707 -0 0</pose>
          <geometry>
            <mesh>
              <scale>0.12 0.12 0.12</scale>
              <uri>/home/csi/Workspace/SRC-Phase2/src/csi_rover_description/meshes/wheel.dae</uri>
            </mesh>
          </geometry>
        </visual>
        <self_collide>0</self_collide>
        <enable_wind>0</enable_wind>
        <kinematic>0</kinematic>
      </link>
      <joint name='right_front_axle' type='revolute'>
        <child>right_front_wheel</child>
        <parent>right_front_axle_link</parent>
        <axis>
          <xyz>0 1 0</xyz>
          <limit>
            <lower>-1e+16</lower>
            <upper>1e+16</upper>
          </limit>
          <dynamics>
            <spring_reference>0</spring_reference>
            <spring_stiffness>0</spring_stiffness>
          </dynamics>
          <use_parent_model_frame>1</use_parent_model_frame>
        </axis>
      </joint>
      <link name='right_rear_axle_link'>
        <pose frame=''>-0.7862 -0.92845 0.2159 0 -0 0</pose>
        <inertial>
          <pose frame=''>0 0 0 0 -0 0</pose>
          <mass>0.001</mass>
          <inertia>
            <ixx>0.001</ixx>
            <ixy>0</ixy>
            <ixz>0</ixz>
            <iyy>0.001</iyy>
            <iyz>0</iyz>
            <izz>0.0001</izz>
          </inertia>
        </inertial>
        <visual name='right_rear_axle_link_fixed_joint_lump__visual_visual'>
          <pose frame=''>0 0 0 3.14159 1.57079 -1.57089</pose>
          <geometry>
            <cylinder>
              <length>0.2</length>
              <radius>0.05</radius>
            </cylinder>
          </geometry>
        </visual>
        <self_collide>0</self_collide>
        <enable_wind>0</enable_wind>
        <kinematic>0</kinematic>
      </link>
      <joint name='right_rear_steering_joint' type='revolute'>
        <child>right_rear_axle_link</child>
        <parent>chassis</parent>
        <axis>
          <xyz>0 0 1</xyz>
          <limit>
            <lower>-1.5707</lower>
            <upper>1.5707</upper>
            <effort>10</effort>
            <velocity>15</velocity>
          </limit>
          <dynamics>
            <spring_reference>0</spring_reference>
            <spring_stiffness>0</spring_stiffness>
          </dynamics>
          <use_parent_model_frame>1</use_parent_model_frame>
        </axis>
      </joint>
      <link name='right_rear_wheel'>
        <pose frame=''>-0.7862 -0.92845 0.2159 0 -0 0</pose>
        <inertial>
          <pose frame=''>0 0 0 1.5707 -0 0</pose>
          <mass>2</mass>
          <inertia>
            <ixx>0.4</ixx>
            <ixy>0</ixy>
            <ixz>0</ixz>
            <iyy>0.4</iyy>
            <iyz>0</iyz>
            <izz>0.2</izz>
          </inertia>
        </inertial>
        <collision name='right_rear_wheel_collision'>
          <pose frame=''>0 0 0 1.5707 -0 0</pose>
          <geometry>
            <cylinder>
              <length>0.0889</length>
              <radius>0.3048</radius>
            </cylinder>
          </geometry>
          <max_contacts>10</max_contacts>
          <surface>
            <contact>
              <ode/>
            </contact>
            <bounce/>
            <friction>
              <torsional>
                <ode/>
              </torsional>
              <ode/>
            </friction>
          </surface>
        </collision>
        <visual name='right_rear_wheel_visual'>
          <pose frame=''>0 0 0 1.5707 -0 0</pose>
          <geometry>
            <mesh>
              <scale>0.12 0.12 0.12</scale>
              <uri>/home/csi/Workspace/SRC-Phase2/src/csi_rover_description/meshes/wheel.dae</uri>
            </mesh>
          </geometry>
        </visual>
        <self_collide>0</self_collide>
        <enable_wind>0</enable_wind>
        <kinematic>0</kinematic>
      </link>
      <joint name='right_rear_axle' type='revolute'>
        <child>right_rear_wheel</child>
        <parent>right_rear_axle_link</parent>
        <axis>
          <xyz>0 1 0</xyz>
          <limit>
            <lower>-1e+16</lower>
            <upper>1e+16</upper>
          </limit>
          <dynamics>
            <spring_reference>0</spring_reference>
            <spring_stiffness>0</spring_stiffness>
          </dynamics>
          <use_parent_model_frame>1</use_parent_model_frame>
        </axis>
      </joint>
      <plugin name='rover_odom' filename='librover_odom.so'>
        <updateRate>30.0</updateRate>
        <robotNamespace>/csi_rover</robotNamespace>
        <robotBaseFrame>chassis</robotBaseFrame>
        <odometryTopic>odom</odometryTopic>
        <odometryFrame>odom</odometryFrame>
      </plugin>
      <plugin name='p3d_base_controller' filename='libgazebo_ros_p3d.so'>
        <alwaysOn>1</alwaysOn>
        <updateRate>50.0</updateRate>
        <bodyName>chassis</bodyName>
        <topicName>/ground_truth</topicName>
        <gaussianNoise>0.01</gaussianNoise>
        <frameName>world</frameName>
        <xyzOffsets>0 0 0</xyzOffsets>
        <rpyOffsets>0 0 0</rpyOffsets>
        <robotNamespace>/</robotNamespace>
      </plugin>
      <static>0</static>
      <plugin name='gazebo_ros_control' filename='libgazebo_ros_control.so'>
        <robotNamespace>/csi_rover</robotNamespace>
        <robotSimType>gazebo_ros_control/DefaultRobotHWSim</robotSimType>
      </plugin>
      <pose frame=''>0 0 0 0 -0 0</pose>
    </model>
    <model name='ambulance'>
      <static>1</static>
      <link name='link'>
        <collision name='collision'>
          <geometry>
            <mesh>
              <scale>0.0254 0.0254 0.0254</scale>
              <uri>model://ambulance/meshes/ambulance.obj</uri>
            </mesh>
          </geometry>
          <max_contacts>10</max_contacts>
          <surface>
            <contact>
              <ode/>
            </contact>
            <bounce/>
            <friction>
              <torsional>
                <ode/>
              </torsional>
              <ode/>
            </friction>
          </surface>
        </collision>
        <visual name='visual'>
          <geometry>
            <mesh>
              <scale>0.0254 0.0254 0.0254</scale>
              <uri>model://ambulance/meshes/ambulance.obj</uri>
            </mesh>
          </geometry>
        </visual>
        <self_collide>0</self_collide>
        <enable_wind>0</enable_wind>
        <kinematic>0</kinematic>
      </link>
      <pose frame=''>22.3602 41.4049 0 0 -0 0</pose>
    </model>
    <model name='apartment'>
      <static>1</static>
      <link name='link'>
        <collision name='collision'>
          <geometry>
            <mesh>
              <uri>model://apartment/meshes/apartment.dae</uri>
            </mesh>
          </geometry>
          <max_contacts>10</max_contacts>
          <surface>
            <contact>
              <ode/>
            </contact>
            <bounce/>
            <friction>
              <torsional>
                <ode/>
              </torsional>
              <ode/>
            </friction>
          </surface>
        </collision>
        <visual name='visual'>
          <geometry>
            <mesh>
              <uri>model://apartment/meshes/apartment.dae</uri>
            </mesh>
          </geometry>
        </visual>
        <self_collide>0</self_collide>
        <enable_wind>0</enable_wind>
        <kinematic>0</kinematic>
      </link>
      <pose frame=''>20.0131 -46.4786 0 0 -0 0</pose>
    </model>
    <model name='fire_station'>
      <static>1</static>
      <link name='link'>
        <collision name='main'>
          <pose frame=''>0 -0.135 5 0 -0 0</pose>
          <geometry>
            <box>
              <size>19.98 9.68 10</size>
            </box>
          </geometry>
          <max_contacts>10</max_contacts>
          <surface>
            <contact>
              <ode/>
            </contact>
            <bounce/>
            <friction>
              <torsional>
                <ode/>
              </torsional>
              <ode/>
            </friction>
          </surface>
        </collision>
        <collision name='front_top'>
          <pose frame=''>0 4.957 7 0 -0 0</pose>
          <geometry>
            <box>
              <size>20 0.515 6</size>
            </box>
          </geometry>
          <max_contacts>10</max_contacts>
          <surface>
            <contact>
              <ode/>
            </contact>
            <bounce/>
            <friction>
              <torsional>
                <ode/>
              </torsional>
              <ode/>
            </friction>
          </surface>
        </collision>
        <collision name='column_0'>
          <pose frame=''>9.333 4.957 2 0 -0 0</pose>
          <geometry>
            <box>
              <size>1.315 0.515 4</size>
            </box>
          </geometry>
          <max_contacts>10</max_contacts>
          <surface>
            <contact>
              <ode/>
            </contact>
            <bounce/>
            <friction>
              <torsional>
                <ode/>
              </torsional>
              <ode/>
            </friction>
          </surface>
        </collision>
        <collision name='column_1'>
          <pose frame=''>3.33 4.957 2 0 -0 0</pose>
          <geometry>
            <box>
              <size>2.63 0.515 4</size>
            </box>
          </geometry>
          <max_contacts>10</max_contacts>
          <surface>
            <contact>
              <ode/>
            </contact>
            <bounce/>
            <friction>
              <torsional>
                <ode/>
              </torsional>
              <ode/>
            </friction>
          </surface>
        </collision>
        <collision name='column_2'>
          <pose frame=''>-3.33 4.957 2 0 -0 0</pose>
          <geometry>
            <box>
              <size>2.63 0.515 4</size>
            </box>
          </geometry>
          <max_contacts>10</max_contacts>
          <surface>
            <contact>
              <ode/>
            </contact>
            <bounce/>
            <friction>
              <torsional>
                <ode/>
              </torsional>
              <ode/>
            </friction>
          </surface>
        </collision>
        <collision name='column_3'>
          <pose frame=''>-9.333 4.957 2 0 -0 0</pose>
          <geometry>
            <box>
              <size>1.315 0.515 4</size>
            </box>
          </geometry>
          <max_contacts>10</max_contacts>
          <surface>
            <contact>
              <ode/>
            </contact>
            <bounce/>
            <friction>
              <torsional>
                <ode/>
              </torsional>
              <ode/>
            </friction>
          </surface>
        </collision>
        <collision name='roof_back'>
          <pose frame=''>0 -2.742 10.467 0.25 -0 0</pose>
          <geometry>
            <box>
              <size>21.47 6.12 0.28</size>
            </box>
          </geometry>
          <max_contacts>10</max_contacts>
          <surface>
            <contact>
              <ode/>
            </contact>
            <bounce/>
            <friction>
              <torsional>
                <ode/>
              </torsional>
              <ode/>
            </friction>
          </surface>
        </collision>
        <collision name='roof_front'>
          <pose frame=''>0 3.12 10.467 -0.25 0 0</pose>
          <geometry>
            <box>
              <size>21.47 6.12 0.28</size>
            </box>
          </geometry>
          <max_contacts>10</max_contacts>
          <surface>
            <contact>
              <ode/>
            </contact>
            <bounce/>
            <friction>
              <torsional>
                <ode/>
              </torsional>
              <ode/>
            </friction>
          </surface>
        </collision>
        <collision name='roof_base'>
          <pose frame=''>0 0.188 9.705 0 -0 0</pose>
          <geometry>
            <box>
              <size>21.47 11.86 0.28</size>
            </box>
          </geometry>
          <max_contacts>10</max_contacts>
          <surface>
            <contact>
              <ode/>
            </contact>
            <bounce/>
            <friction>
              <torsional>
                <ode/>
              </torsional>
              <ode/>
            </friction>
          </surface>
        </collision>
        <collision name='roof_filling_0'>
          <pose frame=''>0 0.188 9.985 0 -0 0</pose>
          <geometry>
            <box>
              <size>21.47 9.53 0.28</size>
            </box>
          </geometry>
          <max_contacts>10</max_contacts>
          <surface>
            <contact>
              <ode/>
            </contact>
            <bounce/>
            <friction>
              <torsional>
                <ode/>
              </torsional>
              <ode/>
            </friction>
          </surface>
        </collision>
        <collision name='roof_filling_1'>
          <pose frame=''>0 0.188 10.14 0 -0 0</pose>
          <geometry>
            <box>
              <size>21.47 8.41 0.28</size>
            </box>
          </geometry>
          <max_contacts>10</max_contacts>
          <surface>
            <contact>
              <ode/>
            </contact>
            <bounce/>
            <friction>
              <torsional>
                <ode/>
              </torsional>
              <ode/>
            </friction>
          </surface>
        </collision>
        <collision name='roof_filling_2'>
          <pose frame=''>0 0.188 10.42 0 -0 0</pose>
          <geometry>
            <box>
              <size>21.47 6.25 0.28</size>
            </box>
          </geometry>
          <max_contacts>10</max_contacts>
          <surface>
            <contact>
              <ode/>
            </contact>
            <bounce/>
            <friction>
              <torsional>
                <ode/>
              </torsional>
              <ode/>
            </friction>
          </surface>
        </collision>
        <collision name='roof_filling_3'>
          <pose frame=''>0 0.188 10.7 0 -0 0</pose>
          <geometry>
            <box>
              <size>21.47 4.05 0.28</size>
            </box>
          </geometry>
          <max_contacts>10</max_contacts>
          <surface>
            <contact>
              <ode/>
            </contact>
            <bounce/>
            <friction>
              <torsional>
                <ode/>
              </torsional>
              <ode/>
            </friction>
          </surface>
        </collision>
        <collision name='roof_filling_4'>
          <pose frame=''>0 0.188 10.98 0 -0 0</pose>
          <geometry>
            <box>
              <size>21.47 1.83 0.28</size>
            </box>
          </geometry>
          <max_contacts>10</max_contacts>
          <surface>
            <contact>
              <ode/>
            </contact>
            <bounce/>
            <friction>
              <torsional>
                <ode/>
              </torsional>
              <ode/>
            </friction>
          </surface>
        </collision>
        <visual name='visual'>
          <geometry>
            <mesh>
              <uri>model://fire_station/meshes/fire_station.dae</uri>
            </mesh>
          </geometry>
        </visual>
        <self_collide>0</self_collide>
        <enable_wind>0</enable_wind>
        <kinematic>0</kinematic>
      </link>
      <pose frame=''>-36.5669 30.8398 0 0 -0 0</pose>
    </model>
    <model name='Construction Cone'>
      <link name='link'>
        <collision name='collision'>
          <geometry>
            <mesh>
              <scale>10 10 10</scale>
              <uri>model://construction_cone/meshes/construction_cone.dae</uri>
            </mesh>
          </geometry>
          <max_contacts>10</max_contacts>
          <surface>
            <contact>
              <ode/>
            </contact>
            <bounce/>
            <friction>
              <torsional>
                <ode/>
              </torsional>
              <ode/>
            </friction>
          </surface>
        </collision>
        <visual name='visual'>
          <geometry>
            <mesh>
              <scale>10 10 10</scale>
              <uri>model://construction_cone/meshes/construction_cone.dae</uri>
            </mesh>
          </geometry>
        </visual>
        <self_collide>0</self_collide>
        <inertial>
          <inertia>
            <ixx>1</ixx>
            <ixy>0</ixy>
            <ixz>0</ixz>
            <iyy>1</iyy>
            <iyz>0</iyz>
            <izz>1</izz>
          </inertia>
          <mass>1</mass>
        </inertial>
        <enable_wind>0</enable_wind>
        <kinematic>0</kinematic>
      </link>
      <pose frame=''>4.82327 17.1392 0 0 -0 0</pose>
    </model>
    <model name='Construction Cone_0'>
      <link name='link'>
        <collision name='collision'>
          <geometry>
            <mesh>
              <scale>10 10 10</scale>
              <uri>model://construction_cone/meshes/construction_cone.dae</uri>
            </mesh>
          </geometry>
          <max_contacts>10</max_contacts>
          <surface>
            <contact>
              <ode/>
            </contact>
            <bounce/>
            <friction>
              <torsional>
                <ode/>
              </torsional>
              <ode/>
            </friction>
          </surface>
        </collision>
        <visual name='visual'>
          <geometry>
            <mesh>
              <scale>10 10 10</scale>
              <uri>model://construction_cone/meshes/construction_cone.dae</uri>
            </mesh>
          </geometry>
        </visual>
        <self_collide>0</self_collide>
        <inertial>
          <inertia>
            <ixx>1</ixx>
            <ixy>0</ixy>
            <ixz>0</ixz>
            <iyy>1</iyy>
            <iyz>0</iyz>
            <izz>1</izz>
          </inertia>
          <mass>1</mass>
        </inertial>
        <enable_wind>0</enable_wind>
        <kinematic>0</kinematic>
      </link>
      <pose frame=''>-1.1658 16.1168 0 0 -0 0</pose>
    </model>
    <model name='Construction Cone_1'>
      <link name='link'>
        <collision name='collision'>
          <geometry>
            <mesh>
              <scale>10 10 10</scale>
              <uri>model://construction_cone/meshes/construction_cone.dae</uri>
            </mesh>
          </geometry>
          <max_contacts>10</max_contacts>
          <surface>
            <contact>
              <ode/>
            </contact>
            <bounce/>
            <friction>
              <torsional>
                <ode/>
              </torsional>
              <ode/>
            </friction>
          </surface>
        </collision>
        <visual name='visual'>
          <geometry>
            <mesh>
              <scale>10 10 10</scale>
              <uri>model://construction_cone/meshes/construction_cone.dae</uri>
            </mesh>
          </geometry>
        </visual>
        <self_collide>0</self_collide>
        <inertial>
          <inertia>
            <ixx>1</ixx>
            <ixy>0</ixy>
            <ixz>0</ixz>
            <iyy>1</iyy>
            <iyz>0</iyz>
            <izz>1</izz>
          </inertia>
          <mass>1</mass>
        </inertial>
        <enable_wind>0</enable_wind>
        <kinematic>0</kinematic>
      </link>
      <pose frame=''>14.8629 -4.76188 0 0 -0 0</pose>
    </model>
    <model name='Construction Cone_2'>
      <link name='link'>
        <collision name='collision'>
          <geometry>
            <mesh>
              <scale>10 10 10</scale>
              <uri>model://construction_cone/meshes/construction_cone.dae</uri>
            </mesh>
          </geometry>
          <max_contacts>10</max_contacts>
          <surface>
            <contact>
              <ode/>
            </contact>
            <bounce/>
            <friction>
              <torsional>
                <ode/>
              </torsional>
              <ode/>
            </friction>
          </surface>
        </collision>
        <visual name='visual'>
          <geometry>
            <mesh>
              <scale>10 10 10</scale>
              <uri>model://construction_cone/meshes/construction_cone.dae</uri>
            </mesh>
          </geometry>
        </visual>
        <self_collide>0</self_collide>
        <inertial>
          <inertia>
            <ixx>1</ixx>
            <ixy>0</ixy>
            <ixz>0</ixz>
            <iyy>1</iyy>
            <iyz>0</iyz>
            <izz>1</izz>
          </inertia>
          <mass>1</mass>
        </inertial>
        <enable_wind>0</enable_wind>
        <kinematic>0</kinematic>
      </link>
      <pose frame=''>12.0835 2.94036 0 0 -0 0</pose>
    </model>
    <model name='Construction Cone_3'>
      <link name='link'>
        <collision name='collision'>
          <geometry>
            <mesh>
              <scale>10 10 10</scale>
              <uri>model://construction_cone/meshes/construction_cone.dae</uri>
            </mesh>
          </geometry>
          <max_contacts>10</max_contacts>
          <surface>
            <contact>
              <ode/>
            </contact>
            <bounce/>
            <friction>
              <torsional>
                <ode/>
              </torsional>
              <ode/>
            </friction>
          </surface>
        </collision>
        <visual name='visual'>
          <geometry>
            <mesh>
              <scale>10 10 10</scale>
              <uri>model://construction_cone/meshes/construction_cone.dae</uri>
            </mesh>
          </geometry>
        </visual>
        <self_collide>0</self_collide>
        <inertial>
          <inertia>
            <ixx>1</ixx>
            <ixy>0</ixy>
            <ixz>0</ixz>
            <iyy>1</iyy>
            <iyz>0</iyz>
            <izz>1</izz>
          </inertia>
          <mass>1</mass>
        </inertial>
        <enable_wind>0</enable_wind>
        <kinematic>0</kinematic>
      </link>
      <pose frame=''>30.6713 28.813 0 0 -0 0</pose>
    </model>
    <model name='Construction Cone_4'>
      <link name='link'>
        <collision name='collision'>
          <geometry>
            <mesh>
              <scale>10 10 10</scale>
              <uri>model://construction_cone/meshes/construction_cone.dae</uri>
            </mesh>
          </geometry>
          <max_contacts>10</max_contacts>
          <surface>
            <contact>
              <ode/>
            </contact>
            <bounce/>
            <friction>
              <torsional>
                <ode/>
              </torsional>
              <ode/>
            </friction>
          </surface>
        </collision>
        <visual name='visual'>
          <geometry>
            <mesh>
              <scale>10 10 10</scale>
              <uri>model://construction_cone/meshes/construction_cone.dae</uri>
            </mesh>
          </geometry>
        </visual>
        <self_collide>0</self_collide>
        <inertial>
          <inertia>
            <ixx>1</ixx>
            <ixy>0</ixy>
            <ixz>0</ixz>
            <iyy>1</iyy>
            <iyz>0</iyz>
            <izz>1</izz>
          </inertia>
          <mass>1</mass>
        </inertial>
        <enable_wind>0</enable_wind>
        <kinematic>0</kinematic>
      </link>
      <pose frame=''>-0.873252 39.8974 0 0 -0 0</pose>
    </model>
    <model name='Construction Cone_5'>
      <link name='link'>
        <collision name='collision'>
          <geometry>
            <mesh>
              <scale>10 10 10</scale>
              <uri>model://construction_cone/meshes/construction_cone.dae</uri>
            </mesh>
          </geometry>
          <max_contacts>10</max_contacts>
          <surface>
            <contact>
              <ode/>
            </contact>
            <bounce/>
            <friction>
              <torsional>
                <ode/>
              </torsional>
              <ode/>
            </friction>
          </surface>
        </collision>
        <visual name='visual'>
          <geometry>
            <mesh>
              <scale>10 10 10</scale>
              <uri>model://construction_cone/meshes/construction_cone.dae</uri>
            </mesh>
          </geometry>
        </visual>
        <self_collide>0</self_collide>
        <inertial>
          <inertia>
            <ixx>1</ixx>
            <ixy>0</ixy>
            <ixz>0</ixz>
            <iyy>1</iyy>
            <iyz>0</iyz>
            <izz>1</izz>
          </inertia>
          <mass>1</mass>
        </inertial>
        <enable_wind>0</enable_wind>
        <kinematic>0</kinematic>
      </link>
      <pose frame=''>-30.4604 13.4836 0 0 -0 0</pose>
    </model>
    <model name='Construction Cone_6'>
      <link name='link'>
        <collision name='collision'>
          <geometry>
            <mesh>
              <scale>10 10 10</scale>
              <uri>model://construction_cone/meshes/construction_cone.dae</uri>
            </mesh>
          </geometry>
          <max_contacts>10</max_contacts>
          <surface>
            <contact>
              <ode/>
            </contact>
            <bounce/>
            <friction>
              <torsional>
                <ode/>
              </torsional>
              <ode/>
            </friction>
          </surface>
        </collision>
        <visual name='visual'>
          <geometry>
            <mesh>
              <scale>10 10 10</scale>
              <uri>model://construction_cone/meshes/construction_cone.dae</uri>
            </mesh>
          </geometry>
        </visual>
        <self_collide>0</self_collide>
        <inertial>
          <inertia>
            <ixx>1</ixx>
            <ixy>0</ixy>
            <ixz>0</ixz>
            <iyy>1</iyy>
            <iyz>0</iyz>
            <izz>1</izz>
          </inertia>
          <mass>1</mass>
        </inertial>
        <enable_wind>0</enable_wind>
        <kinematic>0</kinematic>
      </link>
      <pose frame=''>6.64045 -18.5208 0 0 -0 0</pose>
    </model>
    <model name='Construction Cone_7'>
      <link name='link'>
        <collision name='collision'>
          <geometry>
            <mesh>
              <scale>10 10 10</scale>
              <uri>model://construction_cone/meshes/construction_cone.dae</uri>
            </mesh>
          </geometry>
          <max_contacts>10</max_contacts>
          <surface>
            <contact>
              <ode/>
            </contact>
            <bounce/>
            <friction>
              <torsional>
                <ode/>
              </torsional>
              <ode/>
            </friction>
          </surface>
        </collision>
        <visual name='visual'>
          <geometry>
            <mesh>
              <scale>10 10 10</scale>
              <uri>model://construction_cone/meshes/construction_cone.dae</uri>
            </mesh>
          </geometry>
        </visual>
        <self_collide>0</self_collide>
        <inertial>
          <inertia>
            <ixx>1</ixx>
            <ixy>0</ixy>
            <ixz>0</ixz>
            <iyy>1</iyy>
            <iyz>0</iyz>
            <izz>1</izz>
          </inertia>
          <mass>1</mass>
        </inertial>
        <enable_wind>0</enable_wind>
        <kinematic>0</kinematic>
      </link>
      <pose frame=''>30.8152 -16.895 0 0 -0 0</pose>
    </model>
    <model name='Construction Barrel'>
      <link name='link'>
        <inertial>
          <pose frame=''>0 0 0.4 0 -0 0</pose>
          <mass>500</mass>
          <inertia>
            <ixx>51.2096</ixx>
            <iyy>51.2096</iyy>
            <izz>25</izz>
            <ixy>0</ixy>
            <ixz>0</ixz>
            <iyz>0</iyz>
          </inertia>
        </inertial>
        <collision name='collision'>
          <geometry>
            <mesh>
              <uri>model://construction_barrel/meshes/construction_barrel.dae</uri>
            </mesh>
          </geometry>
          <max_contacts>10</max_contacts>
          <surface>
            <contact>
              <ode/>
            </contact>
            <bounce/>
            <friction>
              <torsional>
                <ode/>
              </torsional>
              <ode/>
            </friction>
          </surface>
        </collision>
        <visual name='visual'>
          <geometry>
            <mesh>
              <uri>model://construction_barrel/meshes/construction_barrel.dae</uri>
            </mesh>
          </geometry>
        </visual>
        <self_collide>0</self_collide>
        <enable_wind>0</enable_wind>
        <kinematic>0</kinematic>
      </link>
      <pose frame=''>-15.2703 20.7185 0 0 -0 0</pose>
    </model>
    <model name='bus'>
      <static>1</static>
      <link name='link'>
        <collision name='collision'>
          <geometry>
            <mesh>
              <scale>0.01 0.01 0.01</scale>
              <uri>model://bus/meshes/bus.obj</uri>
            </mesh>
          </geometry>
          <max_contacts>10</max_contacts>
          <surface>
            <contact>
              <ode/>
            </contact>
            <bounce/>
            <friction>
              <torsional>
                <ode/>
              </torsional>
              <ode/>
            </friction>
          </surface>
        </collision>
        <visual name='visual'>
          <geometry>
            <mesh>
              <scale>0.01 0.01 0.01</scale>
              <uri>model://bus/meshes/bus.obj</uri>
            </mesh>
          </geometry>
        </visual>
        <self_collide>0</self_collide>
        <enable_wind>0</enable_wind>
        <kinematic>0</kinematic>
      </link>
      <pose frame=''>-24.4097 -24.5371 0 0 -0 0</pose>
    </model>
    <state world_name='moon'>
      <sim_time>228 890000000</sim_time>
      <real_time>230 56220048</real_time>
      <wall_time>1582750047 725292983</wall_time>
      <iterations>22889</iterations>
      <model name='Construction Barrel'>
        <pose frame=''>-14.7637 20.0605 1.17993 0.09526 -0.061032 1.84581</pose>
        <scale>1 1 1</scale>
        <link name='link'>
          <pose frame=''>-14.7637 20.0605 1.17993 0.09526 -0.061032 1.84581</pose>
          <velocity>0 0 0 0 -0 0</velocity>
          <acceleration>-0.012123 -0.013705 0.001185 0.032593 -0.030759 0.000755</acceleration>
          <wrench>-6.06156 -6.85253 0.592712 0 -0 0</wrench>
        </link>
      </model>
      <model name='Construction Cone'>
        <pose frame=''>4.82327 17.1392 -0.227453 -1e-06 -0 0</pose>
        <scale>1 1 1</scale>
        <link name='link'>
          <pose frame=''>4.82327 17.1392 -0.227453 -1e-06 -0 0</pose>
          <velocity>0 0 0 0 -0 0</velocity>
          <acceleration>-0 -0 0.001942 -0.02168 0.000639 -0</acceleration>
          <wrench>-0 -0 0.001942 0 -0 0</wrench>
        </link>
      </model>
      <model name='Construction Cone_0'>
        <pose frame=''>-1.15684 16.1252 0.069413 -0.094971 0.095427 0.000128</pose>
        <scale>1 1 1</scale>
        <link name='link'>
          <pose frame=''>-1.15684 16.1252 0.069413 -0.094971 0.095427 0.000128</pose>
          <velocity>0 0 0 0 -0 0</velocity>
          <acceleration>0 0 0 0 -0 0</acceleration>
          <wrench>0 0 0 0 -0 0</wrench>
        </link>
      </model>
      <model name='Construction Cone_1'>
        <pose frame=''>14.8629 -4.76188 0.733332 -1e-06 -0 1e-06</pose>
        <scale>1 1 1</scale>
        <link name='link'>
          <pose frame=''>14.8629 -4.76188 0.733332 -1e-06 -0 1e-06</pose>
          <velocity>0 0 0 0 -0 0</velocity>
          <acceleration>-0 -0 0.001942 -0.02168 0.000639 -0</acceleration>
          <wrench>-0 -0 0.001942 0 -0 0</wrench>
        </link>
      </model>
      <model name='Construction Cone_2'>
        <pose frame=''>12.0835 2.94036 0.733332 -1e-06 -0 1e-06</pose>
        <scale>1 1 1</scale>
        <link name='link'>
          <pose frame=''>12.0835 2.94036 0.733332 -1e-06 -0 1e-06</pose>
          <velocity>0 0 0 0 -0 0</velocity>
          <acceleration>-0 -0 0.001942 -0.02168 0.000639 -0</acceleration>
          <wrench>-0 -0 0.001942 0 -0 0</wrench>
        </link>
      </model>
      <model name='Construction Cone_3'>
        <pose frame=''>30.7009 28.8129 0.293152 -0.000164 0.095412 -0.001713</pose>
        <scale>1 1 1</scale>
        <link name='link'>
          <pose frame=''>30.7009 28.8129 0.293152 -0.000164 0.095412 -0.001713</pose>
          <velocity>0 0 0 0 -0 0</velocity>
          <acceleration>-0 0 -0 0 -0 0</acceleration>
          <wrench>-0 0 -0 0 -0 0</wrench>
        </link>
      </model>
      <model name='Construction Cone_4'>
        <pose frame=''>-0.875109 39.9019 -0.680433 -0.053076 -0.087131 0.004087</pose>
        <scale>1 1 1</scale>
        <link name='link'>
          <pose frame=''>-0.875109 39.9019 -0.680433 -0.053076 -0.087131 0.004087</pose>
          <velocity>0 0 0 0 -0 0</velocity>
          <acceleration>0 -0 -0 0 -0 0</acceleration>
          <wrench>0 -0 -0 0 -0 0</wrench>
        </link>
      </model>
      <model name='Construction Cone_5'>
        <pose frame=''>-30.4836 13.4847 0.528874 0.012557 -0.035181 -0.010263</pose>
        <scale>1 1 1</scale>
        <link name='link'>
          <pose frame=''>-30.4836 13.4847 0.528874 0.012557 -0.035181 -0.010263</pose>
          <velocity>0 0 0 0 -0 0</velocity>
          <acceleration>0 -0 -0 0 -0 0</acceleration>
          <wrench>0 -0 -0 0 -0 0</wrench>
        </link>
      </model>
      <model name='Construction Cone_6'>
        <pose frame=''>6.64045 -18.5208 -0.035295 0 1e-06 0</pose>
        <scale>1 1 1</scale>
        <link name='link'>
          <pose frame=''>6.64045 -18.5208 -0.035295 0 1e-06 0</pose>
          <velocity>0 0 0 0 -0 0</velocity>
          <acceleration>-0 0 0.000234 0.018677 0.019702 0</acceleration>
          <wrench>-0 0 0.000234 0 -0 0</wrench>
        </link>
      </model>
      <model name='Construction Cone_7'>
        <pose frame=''>30.8223 -16.9024 0.133059 0.039541 0.04778 0.001424</pose>
        <scale>1 1 1</scale>
        <link name='link'>
          <pose frame=''>30.8223 -16.9024 0.133059 0.039541 0.04778 0.001424</pose>
          <velocity>0 0 0 0 -0 0</velocity>
          <acceleration>-0 0 0 0 -0 0</acceleration>
          <wrench>-0 0 0 0 -0 0</wrench>
        </link>
      </model>
      <model name='ambulance'>
        <pose frame=''>22.3602 41.4049 0 0 -0 0</pose>
        <scale>1 1 1</scale>
        <link name='link'>
          <pose frame=''>22.3602 41.4049 0 0 -0 0</pose>
          <velocity>0 0 0 0 -0 0</velocity>
          <acceleration>0 0 0 0 -0 0</acceleration>
          <wrench>0 0 0 0 -0 0</wrench>
        </link>
      </model>
      <model name='apartment'>
        <pose frame=''>20.0131 -46.4786 0 0 -0 0</pose>
        <scale>1 1 1</scale>
        <link name='link'>
          <pose frame=''>20.0131 -46.4786 0 0 -0 0</pose>
          <velocity>0 0 0 0 -0 0</velocity>
          <acceleration>0 0 0 0 -0 0</acceleration>
          <wrench>0 0 0 0 -0 0</wrench>
        </link>
      </model>
      <model name='apollo15_landing_site_1000x1000'>
        <pose frame=''>0 0 0 0 -0 0</pose>
        <scale>1 1 1</scale>
        <link name='link'>
          <pose frame=''>0 0 0 0 -0 0</pose>
          <velocity>0 0 0 0 -0 0</velocity>
          <acceleration>0 0 0 0 -0 0</acceleration>
          <wrench>0 0 0 0 -0 0</wrench>
        </link>
      </model>
      <model name='bus'>
        <pose frame=''>-24.4097 -24.5371 0 0 -0 0</pose>
        <scale>1 1 1</scale>
        <link name='link'>
          <pose frame=''>-24.4097 -24.5371 0 0 -0 0</pose>
          <velocity>0 0 0 0 -0 0</velocity>
          <acceleration>0 0 0 0 -0 0</acceleration>
          <wrench>0 0 0 0 -0 0</wrench>
        </link>
      </model>
      <model name='csi_rover'>
        <pose frame=''>-0.178858 4.56317 -0.184645 -0.306907 -0.009403 0.764673</pose>
        <scale>1 1 1</scale>
        <link name='chassis'>
          <pose frame=''>-0.178858 4.56317 -0.184645 -0.306907 -0.009403 0.764673</pose>
          <velocity>0.001524 -0.001455 0.000597 -0.006474 0.001938 0.020133</velocity>
          <acceleration>-0.004226 0.001851 0.000846 -1.58781 1.31279 -0.193423</acceleration>
          <wrench>-0.035512 0.015558 0.007106 0 -0 0</wrench>
        </link>
        <link name='left_front_axle_link'>
          <pose frame=''>-0.263671 5.79695 -0.251788 -0.307808 -0.00947 0.764428</pose>
          <velocity>0.010386 -0.000584 0.003674 0.009399 -0.004572 -0.028902</velocity>
          <acceleration>2.86123 0.105601 0.969466 3.01006 -0.454885 -1.75963</acceleration>
          <wrench>0.002861 0.000106 0.000969 0 -0 0</wrench>
        </link>
        <link name='left_front_wheel'>
          <pose frame=''>-0.265251 5.79597 -0.251822 -2.4981 -1.04199 -2.9548</pose>
          <velocity>0.000328 -0.001609 0.000326 0.006925 -0.004927 -0.029567</velocity>
          <acceleration>0.037315 -0.265932 0.031791 1.58079 -0.410524 1.61577</acceleration>
          <wrench>0.074629 -0.531864 0.063583 0 -0 0</wrench>
        </link>
        <link name='left_rear_axle_link'>
          <pose frame=''>-1.39026 4.69825 -0.229341 -0.313488 -0.009801 0.763172</pose>
          <velocity>0.000992 0.012008 -0.004212 0.002043 0.001174 0.000436</velocity>
          <acceleration>0.196102 3.15884 -0.340327 -2.89929 0.014665 -2.43148</acceleration>
          <wrench>0.000196 0.003159 -0.00034 0 -0 0</wrench>
        </link>
        <link name='left_rear_wheel'>
          <pose frame=''>-1.3941 4.70026 -0.240522 -2.76297 0.593361 -2.16251</pose>
          <velocity>0.000212 0.000332 -0.002308 0.001035 -5e-06 0.00033</velocity>
          <acceleration>-0.01847 -0.055546 0.014949 -2.79191 -1.29572 1.59232</acceleration>
          <wrench>-0.036939 -0.111091 0.029898 0 -0 0</wrench>
        </link>
        <link name='right_front_axle_link'>
          <pose frame=''>0.938118 4.51697 0.331216 -0.308398 -0.009629 0.764296</pose>
          <velocity>-0.002651 -0.010368 0.000224 -0.003415 0.002354 0.014298</velocity>
          <acceleration>-0.40986 -2.95252 0.216194 -3.06771 0.679046 1.06281</acceleration>
          <wrench>-0.00041 -0.002953 0.000216 0 -0 0</wrench>
        </link>
        <link name='right_front_wheel'>
          <pose frame=''>0.94249 4.51569 0.324724 -0.686444 -1.07183 1.38493</pose>
          <velocity>-0.000768 0.000264 -0.000215 -0.004881 0.002726 0.013808</velocity>
          <acceleration>0.028262 0.044966 -0.005901 -2.05848 0.779118 -1.12099</acceleration>
          <wrench>0.056524 0.089932 -0.011802 0 -0 0</wrench>
        </link>
        <link name='right_rear_axle_link'>
          <pose frame=''>-0.180937 3.42433 0.296332 -0.306709 -0.009378 0.764859</pose>
          <velocity>0.037494 0.00236 0.011965 -0.001963 -0.004762 -0.004891</velocity>
          <acceleration>10.5182 0.69726 3.50127 1.4077 0.940936 0.285702</acceleration>
          <wrench>0.010518 0.000697 0.003501 0 -0 0</wrench>
        </link>
        <link name='right_rear_wheel'>
          <pose frame=''>-0.184193 3.42371 0.288662 -2.77748 -0.560267 -2.57953</pose>
          <velocity>-8.2e-05 -4.9e-05 -4.3e-05 0.001785 -0.000414 -0.005154</velocity>
          <acceleration>0.024807 -0.007478 -0.000391 -0.050956 0.311726 -1.98987</acceleration>
          <wrench>0.049613 -0.014956 -0.000782 0 -0 0</wrench>
        </link>
      </model>
      <model name='fire_station'>
        <pose frame=''>-36.5669 30.8398 0 0 -0 0</pose>
        <scale>1 1 1</scale>
        <link name='link'>
          <pose frame=''>-36.5669 30.8398 0 0 -0 0</pose>
          <velocity>0 0 0 0 -0 0</velocity>
          <acceleration>0 0 0 0 -0 0</acceleration>
          <wrench>0 0 0 0 -0 0</wrench>
        </link>
      </model>
      <light name='sun'>
        <pose frame=''>0 0 10 0 -0 0</pose>
      </light>
    </state>
    <gui fullscreen='0'>
      <camera name='user_camera'>
        <pose frame=''>-178.887 -16.4977 99.4636 0 0.457797 0.15301</pose>
        <view_controller>orbit</view_controller>
        <projection_type>perspective</projection_type>
      </camera>
    </gui>
  </world>
</sdf>
